Workbook

Sheet Resumo_NUTSIII
A1: NUTSIII | B1: GD_REF | C1: theta_inv_REF | D1: theta_ver_REF | E1: G_inv_sul_kWhm2mes | F1: G_verao_S_kWhm2mes | G1: G_verao_O_kWhm2mes | H1: G_verao_N_kWhm2mes | I1: G_verao_E_kWhm2mes | J1: z_REF_m | K1: Mref
A2: Alentejo Central | B2: 1150 | C2: 10.0 | D2: 24.3 | E2: 150 | F2: 415 | G2: 510 | H2: 225 | I2: 510 | J2: 221 | K2: 5.3
A3: Alentejo Litoral | B3: 1089 | C3: 10.8 | D3: 22.2 | E3: 150 | F3: 405 | G3: 510 | H3: 225 | I3: 510 | J3: 88 | K3: 5.3
A4: Algarve | B4: 987 | C4: 11.3 | D4: 23.1 | E4: 155 | F4: 405 | G4: 515 | H4: 225 | I4: 515 | J4: 145 | K4: 4.8
A5: Alto Alentejo | B5: 1221 | C5: 9.6 | D5: 24.5 | E5: 145 | F5: 415 | G5: 505 | H5: 225 | I5: 505 | J5: 246 | K5: 5.3
A6: Alto Tras-os-Montes | B6: 2015 | C6: 5.5 | D6: 21.5 | E6: 125 | F6: 425 | G6: 480 | H6: 220 | I6: 480 | J6: 680 | K6: 7.3
A7: Ave | B7: 1653 | C7: 7.8 | D7: 20.8 | E7: 125 | F7: 425 | G7: 490 | H7: 220 | I7: 490 | J7: 426 | K7: 7.2
A8: Baixo Alentejo | B8: 1068 | C8: 10.7 | D8: 24.7 | E8: 155 | F8: 405 | G8: 510 | H8: 225 | I8: 510 | J8: 178 | K8: 5.0
A9: Baixo Mondego | B9: 1304 | C9: 9.7 | D9: 20.9 | E9: 140 | F9: 420 | G9: 495 | H9: 225 | I9: 495 | J9: 67 | K9: 6.3
A10: Baixo Vouga | B10: 1337 | C10: 9.5 | D10: 20.6 | E10: 140 | F10: 520 | G10: 490 | H10: 220 | I10: 490 | J10: 50 | K10: 6.3
A11: Beira Interior Norte | B11: 1924 | C11: 6.3 | D11: 21.7 | E11: 135 | F11: 425 | G11: 495 | H11: 220 | I11: 495 | J11: 717 | K11: 7.5
A12: Beira Interior Sul | B12: 1274 | C12: 9.1 | D12: 25.3 | E12: 140 | F12: 420 | G12: 500 | H12: 220 | I12: 500 | J12: 328 | K12: 5.4
A13: Cavado | B13: 1491 | C13: 9.0 | D13: 20.7 | E13: 125 | F13: 425 | G13: 485 | H13: 220 | I13: 485 | J13: 171 | K13: 6.8
... A29: Tamega | B29: 1570 | C29: 7.8 | D29: 21.4 | E29: 135 | F29: 425 | G29: 490 | H29: 220 | I29: 490 | J29: 320 | K29: 6.7

Sheet Aveiro
A1: Concelho | B1: NUTS III | C1: GD_REF | D1: theta_inv_REF | E1: theta_ver_REF | F1: G_inv_sul_kWhm2mes | G1: G_verao_S_kWhm2mes | H1: G_verao_O_kWhm2mes | I1: G_verao_N_kWhm2mes | J1: G_verao_E_kWhm2mes | K1: z_REF_m | L1: Mref
A2: Águeda | B2: Baixo Vouga | C2: =IF(B2="","",INDEX(Resumo_NUTSIII!$B:$B,MATCH(B2,Resumo_NUTSIII!$A:$A,0))) -> 1337 | D2: =IF(B2="","",INDEX(Resumo_NUTSIII!$C:$C,MATCH(B2,Resumo_NUTSIII!$A:$A,0))) -> 9.5 | E2: =IF(B2="","",INDEX(Resumo_NUTSIII!$D:$D,MATCH(B2,Resumo_NUTSIII!$A:$A,0))) -> 20.6 | F2: =IF(B2="","",INDEX(Resumo_NUTSIII!$E:$E,MATCH(B2,Resumo_NUTSIII!$A:$A,0))) -> 140 | G2: =IF(B2="","",INDEX(Resumo_NUTSIII!$F:$F,MATCH(B2,Resumo_NUTSIII!$A:$A,0))) -> 520 | H2: =IF(B2="","",INDEX(Resumo_NUTSIII!$G:$G,MATCH(B2,Resumo_NUTSIII!$A:$A,0))) -> 490 | I2: =IF(B2="","",INDEX(Resumo_NUTSIII!$H:$H,MATCH(B2,Resumo_NUTSIII!$A:$A,0))) -> 220 | J2: =IF(B2="","",INDEX(Resumo_NUTSIII!$I:$I,MATCH(B2,Resumo_NUTSIII!$A:$A,0))) -> 490 | K2: =IF(B2="","",INDEX(Resumo_NUTSIII!$J:$J,MATCH(B2,Resumo_NUTSIII!$A:$A,0))) -> 50 | L2: =IF(B2="","",INDEX(Resumo_NUTSIII!$K:$K,MATCH(B2,Resumo_NUTSIII!$A:$A,0))) -> 6.3
A3: Albergaria-a-Velha | B3: Baixo Vouga | C3: =IF(B3="","",INDEX(Resumo_NUTSIII!$B:$B,MATCH(B3,Resumo_NUTSIII!$A:$A,0))) -> 1337 | D3: =IF(B3="","",INDEX(Resumo_NUTSIII!$C:$C,MATCH(B3,Resumo_NUTSIII!$A:$A,0))) -> 9.5 | E3: =IF(B3="","",INDEX(Resumo_NUTSIII!$D:$D,MATCH(B3,Resumo_NUTSIII!$A:$A,0))) -> 20.6 | F3: =IF(B3="","",INDEX(Resumo_NUTSIII!$E:$E,MATCH(B3,Resumo_NUTSIII!$A:$A,0))) -> 140 | G3: =IF(B3="","",INDEX(Resumo_NUTSIII!$F:$F,MATCH(B3,Resumo_NUTSIII!$A:$A,0))) -> 520 | H3: =IF(B3="","",INDEX(Resumo_NUTSIII!$G:$G,MATCH(B3,Resumo_NUTSIII!$A:$A,0))) -> 490 | I3: =IF(B3="","",INDEX(Resumo_NUTSIII!$H:$H,MATCH(B3,Resumo_NUTSIII!$A:$A,0))) -> 220 | J3: =IF(B3="","",INDEX(Resumo_NUTSIII!$I:$I,MATCH(B3,Resumo_NUTSIII!$A:$A,0))) -> 490 | K3: =IF(B3="","",INDEX(Resumo_NUTSIII!$J:$J,MATCH(B3,Resumo_NUTSIII!$A:$A,0))) -> 50 | L3: =IF(B3="","",INDEX(Resumo_NUTSIII!$K:$K,MATCH(B3,Resumo_NUTSIII!$A:$A,0))) -> 6.3
A4: Anadia | B4: Baixo Vouga | C4: =IF(B4="","",INDEX(Resumo_NUTSIII!$B:$B,MATCH(B4,Resumo_NUTSIII!$A:$A,0))) -> 1337 | D4: =IF(B4="","",INDEX(Resumo_NUTSIII!$C:$C,MATCH(B4,Resumo_NUTSIII!$A:$A,0))) -> 9.5 | E4: =IF(B4="","",INDEX(Resumo_NUTSIII!$D:$D,MATCH(B4,Resumo_NUTSIII!$A:$A,0))) -> 20.6 | F4: =IF(B4="","",INDEX(Resumo_NUTSIII!$E:$E,MATCH(B4,Resumo_NUTSIII!$A:$A,0))) -> 140 | G4: =IF(B4="","",INDEX(Resumo_NUTSIII!$F:$F,MATCH(B4,Resumo_NUTSIII!$A:$A,0))) -> 520 | H4: =IF(B4="","",INDEX(Resumo_NUTSIII!$G:$G,MATCH(B4,Resumo_NUTSIII!$A:$A,0))) -> 490 | I4: =IF(B4="","",INDEX(Resumo_NUTSIII!$H:$H,MATCH(B4,Resumo_NUTSIII!$A:$A,0))) -> 220 | J4: =IF(B4="","",INDEX(Resumo_NUTSIII!$I:$I,MATCH(B4,Resumo_NUTSIII!$A:$A,0))) -> 490 | K4: =IF(B4="","",INDEX(Resumo_NUTSIII!$J:$J,MATCH(B4,Resumo_NUTSIII!$A:$A,0))) -> 50 | L4: =IF(B4="","",INDEX(Resumo_NUTSIII!$K:$K,MATCH(B4,Resumo_NUTSIII!$A:$A,0))) -> 6.3
A5: Arouca | B5: Entre Douro e Vouga | C5: =IF(B5="","",INDEX(Resumo_NUTSIII!$B:$B,MATCH(B5,Resumo_NUTSIII!$A:$A,0))) -> 1544 | D5: =IF(B5="","",INDEX(Resumo_NUTSIII!$C:$C,MATCH(B5,Resumo_NUTSIII!$A:$A,0))) -> 8.4 | E5: =IF(B5="","",INDEX(Resumo_NUTSIII!$D:$D,MATCH(B5,Resumo_NUTSIII!$A:$A,0))) -> 20.6 | F5: =IF(B5="","",INDEX(Resumo_NUTSIII!$E:$E,MATCH(B5,Resumo_NUTSIII!$A:$A,0))) -> 135 | G5: =IF(B5="","",INDEX(Resumo_NUTSIII!$F:$F,MATCH(B5,Resumo_NUTSIII!$A:$A,0))) -> 425 | H5: =IF(B5="","",INDEX(Resumo_NUTSIII!$G:$G,MATCH(B5,Resumo_NUTSIII!$A:$A,0))) -> 490 | I5: =IF(B5="","",INDEX(Resumo_NUTSIII!$H:$H,MATCH(B5,Resumo_NUTSIII!$A:$A,0))) -> 220 | J5: =IF(B5="","",INDEX(Resumo_NUTSIII!$I:$I,MATCH(B5,Resumo_NUTSIII!$A:$A,0))) -> 490 | K5: =IF(B5="","",INDEX(Resumo_NUTSIII!$J:$J,MATCH(B5,Resumo_NUTSIII!$A:$A,0))) -> 298 | L5: =IF(B5="","",INDEX(Resumo_NUTSIII!$K:$K,MATCH(B5,Resumo_NUTSIII!$A:$A,0))) -> 6.9
A6: Aveiro | B6: Baixo Vouga | C6: =IF(B6="","",INDEX(Resumo_NUTSIII!$B:$B,MATCH(B6,Resumo_NUTSIII!$A:$A,0))) -> 1337 | D6: =IF(B6="","",INDEX(Resumo_NUTSIII!$C:$C,MATCH(B6,Resumo_NUTSIII!$A:$A,0))) -> 9.5 | E6: =IF(B6="","",INDEX(Resumo_NUTSIII!$D:$D,MATCH(B6,Resumo_NUTSIII!$A:$A,0))) -> 20.6 | F6: =IF(B6="","",INDEX(Resumo_NUTSIII!$E:$E,MATCH(B6,Resumo_NUTSIII!$A:$A,0))) -> 140 | G6: =IF(B6="","",INDEX(Resumo_NUTSIII!$F:$F,MATCH(B6,Resumo_NUTSIII!$A:$A,0))) -> 520 | H6: =IF(B6="","",INDEX(Resumo_NUTSIII!$G:$G,MATCH(B6,Resumo_NUTSIII!$A:$A,0))) -> 490 | I6: =IF(B6="","",INDEX(Resumo_NUTSIII!$H:$H,MATCH(B6,Resumo_NUTSIII!$A:$A,0))) -> 220 | J6: =IF(B6="","",INDEX(Resumo_NUTSIII!$I:$I,MATCH(B6,Resumo_NUTSIII!$A:$A,0))) -> 490 | K6: =IF(B6="","",INDEX(Resumo_NUTSIII!$J:$J,MATCH(B6,Resumo_NUTSIII!$A:$A,0))) -> 50 | L6: =IF(B6="","",INDEX(Resumo_NUTSIII!$K:$K,MATCH(B6,Resumo_NUTSIII!$A:$A,0))) -> 6.3
A7: Castelo de Paiva | B7: Tamega | C7: =IF(B7="","",INDEX(Resumo_NUTSIII!$B:$B,MATCH(B7,Resumo_NUTSIII!$A:$A,0))) -> 1570 | D7: =IF(B7="","",INDEX(Resumo_NUTSIII!$C:$C,MATCH(B7,Resumo_NUTSIII!$A:$A,0))) -> 7.8 | E7: =IF(B7="","",INDEX(Resumo_NUTSIII!$D:$D,MATCH(B7,Resumo_NUTSIII!$A:$A,0))) -> 21.4 | F7: =IF(B7="","",INDEX(Resumo_NUTSIII!$E:$E,MATCH(B7,Resumo_NUTSIII!$A:$A,0))) -> 135 | G7: =IF(B7="","",INDEX(Resumo_NUTSIII!$F:$F,MATCH(B7,Resumo_NUTSIII!$A:$A,0))) -> 425 | H7: =IF(B7="","",INDEX(Resumo_NUTSIII!$G:$G,MATCH(B7,Resumo_NUTSIII!$A:$A,0))) -> 490 | I7: =IF(B7="","",INDEX(Resumo_NUTSIII!$H:$H,MATCH(B7,Resumo_NUTSIII!$A:$A,0))) -> 220 | J7: =IF(B7="","",INDEX(Resumo_NUTSIII!$I:$I,MATCH(B7,Resumo_NUTSIII!$A:$A,0))) -> 490 | K7: =IF(B7="","",INDEX(Resumo_NUTSIII!$J:$J,MATCH(B7,Resumo_NUTSIII!$A:$A,0))) -> 320 | L7: =IF(B7="","",INDEX(Resumo_NUTSIII!$K:$K,MATCH(B7,Resumo_NUTSIII!$A:$A,0))) -> 6.7
A8: Espinho | B8: Entre Douro e Vouga | C8: =IF(B8="","",INDEX(Resumo_NUTSIII!$B:$B,MATCH(B8,Resumo_NUTSIII!$A:$A,0))) -> 1544 | D8: =IF(B8="","",INDEX(Resumo_NUTSIII!$C:$C,MATCH(B8,Resumo_NUTSIII!$A:$A,0))) -> 8.4 | E8: =IF(B8="","",INDEX(Resumo_NUTSIII!$D:$D,MATCH(B8,Resumo_NUTSIII!$A:$A,0))) -> 20.6 | F8: =IF(B8="","",INDEX(Resumo_NUTSIII!$E:$E,MATCH(B8,Resumo_NUTSIII!$A:$A,0))) -> 135 | G8: =IF(B8="","",INDEX(Resumo_NUTSIII!$F:$F,MATCH(B8,Resumo_NUTSIII!$A:$A,0))) -> 425 | H8: =IF(B8="","",INDEX(Resumo_NUTSIII!$G:$G,MATCH(B8,Resumo_NUTSIII!$A:$A,0))) -> 490 | I8: =IF(B8="","",INDEX(Resumo_NUTSIII!$H:$H,MATCH(B8,Resumo_NUTSIII!$A:$A,0))) -> 220 | J8: =IF(B8="","",INDEX(Resumo_NUTSIII!$I:$I,MATCH(B8,Resumo_NUTSIII!$A:$A,0))) -> 490 | K8: =IF(B8="","",INDEX(Resumo_NUTSIII!$J:$J,MATCH(B8,Resumo_NUTSIII!$A:$A,0))) -> 298 | L8: =IF(B8="","",INDEX(Resumo_NUTSIII!$K:$K,MATCH(B8,Resumo_NUTSIII!$A:$A,0))) -> 6.9
A9: Estarreja | B9: Baixo Vouga | C9: =IF(B9="","",INDEX(Resumo_NUTSIII!$B:$B,MATCH(B9,Resumo_NUTSIII!$A:$A,0))) -> 1337 | D9: =IF(B9="","",INDEX(Resumo_NUTSIII!$C:$C,MATCH(B9,Resumo_NUTSIII!$A:$A,0))) -> 9.5 | E9: =IF(B9="","",INDEX(Resumo_NUTSIII!$D:$D,MATCH(B9,Resumo_NUTSIII!$A:$A,0))) -> 20.6 | F9: =IF(B9="","",INDEX(Resumo_NUTSIII!$E:$E,MATCH(B9,Resumo_NUTSIII!$A:$A,0))) -> 140 | G9: =IF(B9="","",INDEX(Resumo_NUTSIII!$F:$F,MATCH(B9,Resumo_NUTSIII!$A:$A,0))) -> 520 | H9: =IF(B9="","",INDEX(Resumo_NUTSIII!$G:$G,MATCH(B9,Resumo_NUTSIII!$A:$A,0))) -> 490 | I9: =IF(B9="","",INDEX(Resumo_NUTSIII!$H:$H,MATCH(B9,Resumo_NUTSIII!$A:$A,0))) -> 220 | J9: =IF(B9="","",INDEX(Resumo_NUTSIII!$I:$I,MATCH(B9,Resumo_NUTSIII!$A:$A,0))) -> 490 | K9: =IF(B9="","",INDEX(Resumo_NUTSIII!$J:$J,MATCH(B9,Resumo_NUTSIII!$A:$A,0))) -> 50 | L9: =IF(B9="","",INDEX(Resumo_NUTSIII!$K:$K,MATCH(B9,Resumo_NUTSIII!$A:$A,0))) -> 6.3
A10: Ílhavo | B10: Baixo Vouga | C10: =IF(B10="","",INDEX(Resumo_NUTSIII!$B:$B,MATCH(B10,Resumo_NUTSIII!$A:$A,0))) -> 1337 | D10: =IF(B10="","",INDEX(Resumo_NUTSIII!$C:$C,MATCH(B10,Resumo_NUTSIII!$A:$A,0))) -> 9.5 | E10: =IF(B10="","",INDEX(Resumo_NUTSIII!$D:$D,MATCH(B10,Resumo_NUTSIII!$A:$A,0))) -> 20.6 | F10: =IF(B10="","",INDEX(Resumo_NUTSIII!$E:$E,MATCH(B10,Resumo_NUTSIII!$A:$A,0))) -> 140 | G10: =IF(B10="","",INDEX(Resumo_NUTSIII!$F:$F,MATCH(B10,Resumo_NUTSIII!$A:$A,0))) -> 520 | H10: =IF(B10="","",INDEX(Resumo_NUTSIII!$G:$G,MATCH(B10,Resumo_NUTSIII!$A:$A,0))) -> 490 | I10: =IF(B10="","",INDEX(Resumo_NUTSIII!$H:$H,MATCH(B10,Resumo_NUTSIII!$A:$A,0))) -> 220 | J10: =IF(B10="","",INDEX(Resumo_NUTSIII!$I:$I,MATCH(B10,Resumo_NUTSIII!$A:$A,0))) -> 490 | K10: =IF(B10="","",INDEX(Resumo_NUTSIII!$J:$J,MATCH(B10,Resumo_NUTSIII!$A:$A,0))) -> 50 | L10: =IF(B10="","",INDEX(Resumo_NUTSIII!$K:$K,MATCH(B10,Resumo_NUTSIII!$A:$A,0))) -> 6.3
A11: Mealhada | B11: Baixo Mondego | C11: =IF(B11="","",INDEX(Resumo_NUTSIII!$B:$B,MATCH(B11,Resumo_NUTSIII!$A:$A,0))) -> 1304 | D11: =IF(B11="","",INDEX(Resumo_NUTSIII!$C:$C,MATCH(B11,Resumo_NUTSIII!$A:$A,0))) -> 9.7 | E11: =IF(B11="","",INDEX(Resumo_NUTSIII!$D:$D,MATCH(B11,Resumo_NUTSIII!$A:$A,0))) -> 20.9 | F11: =IF(B11="","",INDEX(Resumo_NUTSIII!$E:$E,MATCH(B11,Resumo_NUTSIII!$A:$A,0))) -> 140 | G11: =IF(B11="","",INDEX(Resumo_NUTSIII!$F:$F,MATCH(B11,Resumo_NUTSIII!$A:$A,0))) -> 420 | H11: =IF(B11="","",INDEX(Resumo_NUTSIII!$G:$G,MATCH(B11,Resumo_NUTSIII!$A:$A,0))) -> 495 | I11: =IF(B11="","",INDEX(Resumo_NUTSIII!$H:$H,MATCH(B11,Resumo_NUTSIII!$A:$A,0))) -> 225 | J11: =IF(B11="","",INDEX(Resumo_NUTSIII!$I:$I,MATCH(B11,Resumo_NUTSIII!$A:$A,0))) -> 495 | K11: =IF(B11="","",INDEX(Resumo_NUTSIII!$J:$J,MATCH(B11,Resumo_NUTSIII!$A:$A,0))) -> 67 | L11: =IF(B11="","",INDEX(Resumo_NUTSIII!$K:$K,MATCH(B11,Resumo_NUTSIII!$A:$A,0))) -> 6.3
A12: Murtosa | B12: Baixo Vouga | C12: =IF(B12="","",INDEX(Resumo_NUTSIII!$B:$B,MATCH(B12,Resumo_NUTSIII!$A:$A,0))) -> 1337 | D12: =IF(B12="","",INDEX(Resumo_NUTSIII!$C:$C,MATCH(B12,Resumo_NUTSIII!$A:$A,0))) -> 9.5 | E12: =IF(B12="","",INDEX(Resumo_NUTSIII!$D:$D,MATCH(B12,Resumo_NUTSIII!$A:$A,0))) -> 20.6 | F12: =IF(B12="","",INDEX(Resumo_NUTSIII!$E:$E,MATCH(B12,Resumo_NUTSIII!$A:$A,0))) -> 140 | G12: =IF(B12="","",INDEX(Resumo_NUTSIII!$F:$F,MATCH(B12,Resumo_NUTSIII!$A:$A,0))) -> 520 | H12: =IF(B12="","",INDEX(Resumo_NUTSIII!$G:$G,MATCH(B12,Resumo_NUTSIII!$A:$A,0))) -> 490 | I12: =IF(B12="","",INDEX(Resumo_NUTSIII!$H:$H,MATCH(B12,Resumo_NUTSIII!$A:$A,0))) -> 220 | J12: =IF(B12="","",INDEX(Resumo_NUTSIII!$I:$I,MATCH(B12,Resumo_NUTSIII!$A:$A,0))) -> 490 | K12: =IF(B12="","",INDEX(Resumo_NUTSIII!$J:$J,MATCH(B12,Resumo_NUTSIII!$A:$A,0))) -> 50 | L12: =IF(B12="","",INDEX(Resumo_NUTSIII!$K:$K,MATCH(B12,Resumo_NUTSIII!$A:$A,0))) -> 6.3
A13: Oliveira de Azeméis | B13: Entre Douro e Vouga | C13: =IF(B13="","",INDEX(Resumo_NUTSIII!$B:$B,MATCH(B13,Resumo_NUTSIII!$A:$A,0))) -> 1544 | D13: =IF(B13="","",INDEX(Resumo_NUTSIII!$C:$C,MATCH(B13,Resumo_NUTSIII!$A:$A,0))) -> 8.4 | E13: =IF(B13="","",INDEX(Resumo_NUTSIII!$D:$D,MATCH(B13,Resumo_NUTSIII!$A:$A,0))) -> 20.6 | F13: =IF(B13="","",INDEX(Resumo_NUTSIII!$E:$E,MATCH(B13,Resumo_NUTSIII!$A:$A,0))) -> 135 | G13: =IF(B13="","",INDEX(Resumo_NUTSIII!$F:$F,MATCH(B13,Resumo_NUTSIII!$A:$A,0))) -> 425 | H13: =IF(B13="","",INDEX(Resumo_NUTSIII!$G:$G,MATCH(B13,Resumo_NUTSIII!$A:$A,0))) -> 490 | I13: =IF(B13="","",INDEX(Resumo_NUTSIII!$H:$H,MATCH(B13,Resumo_NUTSIII!$A:$A,0))) -> 220 | J13: =IF(B13="","",INDEX(Resumo_NUTSIII!$I:$I,MATCH(B13,Resumo_NUTSIII!$A:$A,0))) -> 490 | K13: =IF(B13="","",INDEX(Resumo_NUTSIII!$J:$J,MATCH(B13,Resumo_NUTSIII!$A:$A,0))) -> 298 | L13: =IF(B13="","",INDEX(Resumo_NUTSIII!$K:$K,MATCH(B13,Resumo_NUTSIII!$A:$A,0))) -> 6.9
... A20: Vale de Cambra | B20: Entre Douro e Vouga | C20: =IF(B20="","",INDEX(Resumo_NUTSIII!$B:$B,MATCH(B20,Resumo_NUTSIII!$A:$A,0))) -> 1544 | D20: =IF(B20="","",INDEX(Resumo_NUTSIII!$C:$C,MATCH(B20,Resumo_NUTSIII!$A:$A,0))) -> 8.4 | E20: =IF(B20="","",INDEX(Resumo_NUTSIII!$D:$D,MATCH(B20,Resumo_NUTSIII!$A:$A,0))) -> 20.6 | F20: =IF(B20="","",INDEX(Resumo_NUTSIII!$E:$E,MATCH(B20,Resumo_NUTSIII!$A:$A,0))) -> 135 | G20: =IF(B20="","",INDEX(Resumo_NUTSIII!$F:$F,MATCH(B20,Resumo_NUTSIII!$A:$A,0))) -> 425 | H20: =IF(B20="","",INDEX(Resumo_NUTSIII!$G:$G,MATCH(B20,Resumo_NUTSIII!$A:$A,0))) -> 490 | I20: =IF(B20="","",INDEX(Resumo_NUTSIII!$H:$H,MATCH(B20,Resumo_NUTSIII!$A:$A,0))) -> 220 | J20: =IF(B20="","",INDEX(Resumo_NUTSIII!$I:$I,MATCH(B20,Resumo_NUTSIII!$A:$A,0))) -> 490 | K20: =IF(B20="","",INDEX(Resumo_NUTSIII!$J:$J,MATCH(B20,Resumo_NUTSIII!$A:$A,0))) -> 298 | L20: =IF(B20="","",INDEX(Resumo_NUTSIII!$K:$K,MATCH(B20,Resumo_NUTSIII!$A:$A,0))) -> 6.9

Sheet Beja
A1: Concelho | B1: NUTS III | C1: GD_REF | D1: theta_inv_REF | E1: theta_ver_REF | F1: G_inv_sul_kWhm2mes | G1: G_verao_S_kWhm2mes | H1: G_verao_O_kWhm2mes | I1: G_verao_N_kWhm2mes | J1: G_verao_E_kWhm2mes | K1: z_REF_m | L1: Mref
A2: Aljustrel | B2: Baixo Alentejo | C2: =IF(B2="","",INDEX(Resumo_NUTSIII!$B:$B,MATCH(B2,Resumo_NUTSIII!$A:$A,0))) -> 1068 | D2: =IF(B2="","",INDEX(Resumo_NUTSIII!$C:$C,MATCH(B2,Resumo_NUTSIII!$A:$A,0))) -> 10.7 | E2: =IF(B2="","",INDEX(Resumo_NUTSIII!$D:$D,MATCH(B2,Resumo_NUTSIII!$A:$A,0))) -> 24.7 | F2: =IF(B2="","",INDEX(Resumo_NUTSIII!$E:$E,MATCH(B2,Resumo_NUTSIII!$A:$A,0))) -> 155 | G2: =IF(B2="","",INDEX(Resumo_NUTSIII!$F:$F,MATCH(B2,Resumo_NUTSIII!$A:$A,0))) -> 405 | H2: =IF(B2="","",INDEX(Resumo_NUTSIII!$G:$G,MATCH(B2,Resumo_NUTSIII!$A:$A,0))) -> 510 | I2: =IF(B2="","",INDEX(Resumo_NUTSIII!$H:$H,MATCH(B2,Resumo_NUTSIII!$A:$A,0))) -> 225 | J2: =IF(B2="","",INDEX(Resumo_NUTSIII!$I:$I,MATCH(B2,Resumo_NUTSIII!$A:$A,0))) -> 510 | K2: =IF(B2="","",INDEX(Resumo_NUTSIII!$J:$J,MATCH(B2,Resumo_NUTSIII!$A:$A,0))) -> 178 | L2: =IF(B2="","",INDEX(Resumo_NUTSIII!$K:$K,MATCH(B2,Resumo_NUTSIII!$A:$A,0))) -> 5.0
A3: Almodôvar | B3: Baixo Alentejo | C3: =IF(B3="","",INDEX(Resumo_NUTSIII!$B:$B,MATCH(B3,Resumo_NUTSIII!$A:$A,0))) -> 1068 | D3: =IF(B3="","",INDEX(Resumo_NUTSIII!$C:$C,MATCH(B3,Resumo_NUTSIII!$A:$A,0))) -> 10.7 | E3: =IF(B3="","",INDEX(Resumo_NUTSIII!$D:$D,MATCH(B3,Resumo_NUTSIII!$A:$A,0))) -> 24.7 | F3: =IF(B3="","",INDEX(Resumo_NUTSIII!$E:$E,MATCH(B3,Resumo_NUTSIII!$A:$A,0))) -> 155 | G3: =IF(B3="","",INDEX(Resumo_NUTSIII!$F:$F,MATCH(B3,Resumo_NUTSIII!$A:$A,0))) -> 405 | H3: =IF(B3="","",INDEX(Resumo_NUTSIII!$G:$G,MATCH(B3,Resumo_NUTSIII!$A:$A,0))) -> 510 | I3: =IF(B3="","",INDEX(Resumo_NUTSIII!$H:$H,MATCH(B3,Resumo_NUTSIII!$A:$A,0))) -> 225 | J3: =IF(B3="","",INDEX(Resumo_NUTSIII!$I:$I,MATCH(B3,Resumo_NUTSIII!$A:$A,0))) -> 510 | K3: =IF(B3="","",INDEX(Resumo_NUTSIII!$J:$J,MATCH(B3,Resumo_NUTSIII!$A:$A,0))) -> 178 | L3: =IF(B3="","",INDEX(Resumo_NUTSIII!$K:$K,MATCH(B3,Resumo_NUTSIII!$A:$A,0))) -> 5.0
A4: Alvito | B4: Baixo Alentejo | C4: =IF(B4="","",INDEX(Resumo_NUTSIII!$B:$B,MATCH(B4,Resumo_NUTSIII!$A:$A,0))) -> 1068 | D4: =IF(B4="","",INDEX(Resumo_NUTSIII!$C:$C,MATCH(B4,Resumo_NUTSIII!$A:$A,0))) -> 10.7 | E4: =IF(B4="","",INDEX(Resumo_NUTSIII!$D:$D,MATCH(B4,Resumo_NUTSIII!$A:$A,0))) -> 24.7 | F4: =IF(B4="","",INDEX(Resumo_NUTSIII!$E:$E,MATCH(B4,Resumo_NUTSIII!$A:$A,0))) -> 155 | G4: =IF(B4="","",INDEX(Resumo_NUTSIII!$F:$F,MATCH(B4,Resumo_NUTSIII!$A:$A,0))) -> 405 | H4: =IF(B4="","",INDEX(Resumo_NUTSIII!$G:$G,MATCH(B4,Resumo_NUTSIII!$A:$A,0))) -> 510 | I4: =IF(B4="","",INDEX(Resumo_NUTSIII!$H:$H,MATCH(B4,Resumo_NUTSIII!$A:$A,0))) -> 225 | J4: =IF(B4="","",INDEX(Resumo_NUTSIII!$I:$I,MATCH(B4,Resumo_NUTSIII!$A:$A,0))) -> 510 | K4: =IF(B4="","",INDEX(Resumo_NUTSIII!$J:$J,MATCH(B4,Resumo_NUTSIII!$A:$A,0))) -> 178 | L4: =IF(B4="","",INDEX(Resumo_NUTSIII!$K:$K,MATCH(B4,Resumo_NUTSIII!$A:$A,0))) -> 5.0
A5: Barrancos | B5: Baixo Alentejo | C5: =IF(B5="","",INDEX(Resumo_NUTSIII!$B:$B,MATCH(B5,Resumo_NUTSIII!$A:$A,0))) -> 1068 | D5: =IF(B5="","",INDEX(Resumo_NUTSIII!$C:$C,MATCH(B5,Resumo_NUTSIII!$A:$A,0))) -> 10.7 | E5: =IF(B5="","",INDEX(Resumo_NUTSIII!$D:$D,MATCH(B5,Resumo_NUTSIII!$A:$A,0))) -> 24.7 | F5: =IF(B5="","",INDEX(Resumo_NUTSIII!$E:$E,MATCH(B5,Resumo_NUTSIII!$A:$A,0))) -> 155 | G5: =IF(B5="","",INDEX(Resumo_NUTSIII!$F:$F,MATCH(B5,Resumo_NUTSIII!$A:$A,0))) -> 405 | H5: =IF(B5="","",INDEX(Resumo_NUTSIII!$G:$G,MATCH(B5,Resumo_NUTSIII!$A:$A,0))) -> 510 | I5: =IF(B5="","",INDEX(Resumo_NUTSIII!$H:$H,MATCH(B5,Resumo_NUTSIII!$A:$A,0))) -> 225 | J5: =IF(B5="","",INDEX(Resumo_NUTSIII!$I:$I,MATCH(B5,Resumo_NUTSIII!$A:$A,0))) -> 510 | K5: =IF(B5="","",INDEX(Resumo_NUTSIII!$J:$J,MATCH(B5,Resumo_NUTSIII!$A:$A,0))) -> 178 | L5: =IF(B5="","",INDEX(Resumo_NUTSIII!$K:$K,MATCH(B5,Resumo_NUTSIII!$A:$A,0))) -> 5.0
A6: Beja | B6: Baixo Alentejo | C6: =IF(B6="","",INDEX(Resumo_NUTSIII!$B:$B,MATCH(B6,Resumo_NUTSIII!$A:$A,0))) -> 1068 | D6: =IF(B6="","",INDEX(Resumo_NUTSIII!$C:$C,MATCH(B6,Resumo_NUTSIII!$A:$A,0))) -> 10.7 | E6: =IF(B6="","",INDEX(Resumo_NUTSIII!$D:$D,MATCH(B6,Resumo_NUTSIII!$A:$A,0))) -> 24.7 | F6: =IF(B6="","",INDEX(Resumo_NUTSIII!$E:$E,MATCH(B6,Resumo_NUTSIII!$A:$A,0))) -> 155 | G6: =IF(B6="","",INDEX(Resumo_NUTSIII!$F:$F,MATCH(B6,Resumo_NUTSIII!$A:$A,0))) -> 405 | H6: =IF(B6="","",INDEX(Resumo_NUTSIII!$G:$G,MATCH(B6,Resumo_NUTSIII!$A:$A,0))) -> 510 | I6: =IF(B6="","",INDEX(Resumo_NUTSIII!$H:$H,MATCH(B6,Resumo_NUTSIII!$A:$A,0))) -> 225 | J6: =IF(B6="","",INDEX(Resumo_NUTSIII!$I:$I,MATCH(B6,Resumo_NUTSIII!$A:$A,0))) -> 510 | K6: =IF(B6="","",INDEX(Resumo_NUTSIII!$J:$J,MATCH(B6,Resumo_NUTSIII!$A:$A,0))) -> 178 | L6: =IF(B6="","",INDEX(Resumo_NUTSIII!$K:$K,MATCH(B6,Resumo_NUTSIII!$A:$A,0))) -> 5.0
A7: Castro Verde | B7: Baixo Alentejo | C7: =IF(B7="","",INDEX(Resumo_NUTSIII!$B:$B,MATCH(B7,Resumo_NUTSIII!$A:$A,0))) -> 1068 | D7: =IF(B7="","",INDEX(Resumo_NUTSIII!$C:$C,MATCH(B7,Resumo_NUTSIII!$A:$A,0))) -> 10.7 | E7: =IF(B7="","",INDEX(Resumo_NUTSIII!$D:$D,MATCH(B7,Resumo_NUTSIII!$A:$A,0))) -> 24.7 | F7: =IF(B7="","",INDEX(Resumo_NUTSIII!$E:$E,MATCH(B7,Resumo_NUTSIII!$A:$A,0))) -> 155 | G7: =IF(B7="","",INDEX(Resumo_NUTSIII!$F:$F,MATCH(B7,Resumo_NUTSIII!$A:$A,0))) -> 405 | H7: =IF(B7="","",INDEX(Resumo_NUTSIII!$G:$G,MATCH(B7,Resumo_NUTSIII!$A:$A,0))) -> 510 | I7: =IF(B7="","",INDEX(Resumo_NUTSIII!$H:$H,MATCH(B7,Resumo_NUTSIII!$A:$A,0))) -> 225 | J7: =IF(B7="","",INDEX(Resumo_NUTSIII!$I:$I,MATCH(B7,Resumo_NUTSIII!$A:$A,0))) -> 510 | K7: =IF(B7="","",INDEX(Resumo_NUTSIII!$J:$J,MATCH(B7,Resumo_NUTSIII!$A:$A,0))) -> 178 | L7: =IF(B7="","",INDEX(Resumo_NUTSIII!$K:$K,MATCH(B7,Resumo_NUTSIII!$A:$A,0))) -> 5.0
A8: Cuba | B8: Baixo Alentejo | C8: =IF(B8="","",INDEX(Resumo_NUTSIII!$B:$B,MATCH(B8,Resumo_NUTSIII!$A:$A,0))) -> 1068 | D8: =IF(B8="","",INDEX(Resumo_NUTSIII!$C:$C,MATCH(B8,Resumo_NUTSIII!$A:$A,0))) -> 10.7 | E8: =IF(B8="","",INDEX(Resumo_NUTSIII!$D:$D,MATCH(B8,Resumo_NUTSIII!$A:$A,0))) -> 24.7 | F8: =IF(B8="","",INDEX(Resumo_NUTSIII!$E:$E,MATCH(B8,Resumo_NUTSIII!$A:$A,0))) -> 155 | G8: =IF(B8="","",INDEX(Resumo_NUTSIII!$F:$F,MATCH(B8,Resumo_NUTSIII!$A:$A,0))) -> 405 | H8: =IF(B8="","",INDEX(Resumo_NUTSIII!$G:$G,MATCH(B8,Resumo_NUTSIII!$A:$A,0))) -> 510 | I8: =IF(B8="","",INDEX(Resumo_NUTSIII!$H:$H,MATCH(B8,Resumo_NUTSIII!$A:$A,0))) -> 225 | J8: =IF(B8="","",INDEX(Resumo_NUTSIII!$I:$I,MATCH(B8,Resumo_NUTSIII!$A:$A,0))) -> 510 | K8: =IF(B8="","",INDEX(Resumo_NUTSIII!$J:$J,MATCH(B8,Resumo_NUTSIII!$A:$A,0))) -> 178 | L8: =IF(B8="","",INDEX(Resumo_NUTSIII!$K:$K,MATCH(B8,Resumo_NUTSIII!$A:$A,0))) -> 5.0
A9: Ferreira do Alentejo | B9: Baixo Alentejo | C9: =IF(B9="","",INDEX(Resumo_NUTSIII!$B:$B,MATCH(B9,Resumo_NUTSIII!$A:$A,0))) -> 1068 | D9: =IF(B9="","",INDEX(Resumo_NUTSIII!$C:$C,MATCH(B9,Resumo_NUTSIII!$A:$A,0))) -> 10.7 | E9: =IF(B9="","",INDEX(Resumo_NUTSIII!$D:$D,MATCH(B9,Resumo_NUTSIII!$A:$A,0))) -> 24.7 | F9: =IF(B9="","",INDEX(Resumo_NUTSIII!$E:$E,MATCH(B9,Resumo_NUTSIII!$A:$A,0))) -> 155 | G9: =IF(B9="","",INDEX(Resumo_NUTSIII!$F:$F,MATCH(B9,Resumo_NUTSIII!$A:$A,0))) -> 405 | H9: =IF(B9="","",INDEX(Resumo_NUTSIII!$G:$G,MATCH(B9,Resumo_NUTSIII!$A:$A,0))) -> 510 | I9: =IF(B9="","",INDEX(Resumo_NUTSIII!$H:$H,MATCH(B9,Resumo_NUTSIII!$A:$A,0))) -> 225 | J9: =IF(B9="","",INDEX(Resumo_NUTSIII!$I:$I,MATCH(B9,Resumo_NUTSIII!$A:$A,0))) -> 510 | K9: =IF(B9="","",INDEX(Resumo_NUTSIII!$J:$J,MATCH(B9,Resumo_NUTSIII!$A:$A,0))) -> 178 | L9: =IF(B9="","",INDEX(Resumo_NUTSIII!$K:$K,MATCH(B9,Resumo_NUTSIII!$A:$A,0))) -> 5.0
A10: Mértola | B10: Baixo Alentejo | C10: =IF(B10="","",INDEX(Resumo_NUTSIII!$B:$B,MATCH(B10,Resumo_NUTSIII!$A:$A,0))) -> 1068 | D10: =IF(B10="","",INDEX(Resumo_NUTSIII!$C:$C,MATCH(B10,Resumo_NUTSIII!$A:$A,0))) -> 10.7 | E10: =IF(B10="","",INDEX(Resumo_NUTSIII!$D:$D,MATCH(B10,Resumo_NUTSIII!$A:$A,0))) -> 24.7 | F10: =IF(B10="","",INDEX(Resumo_NUTSIII!$E:$E,MATCH(B10,Resumo_NUTSIII!$A:$A,0))) -> 155 | G10: =IF(B10="","",INDEX(Resumo_NUTSIII!$F:$F,MATCH(B10,Resumo_NUTSIII!$A:$A,0))) -> 405 | H10: =IF(B10="","",INDEX(Resumo_NUTSIII!$G:$G,MATCH(B10,Resumo_NUTSIII!$A:$A,0))) -> 510 | I10: =IF(B10="","",INDEX(Resumo_NUTSIII!$H:$H,MATCH(B10,Resumo_NUTSIII!$A:$A,0))) -> 225 | J10: =IF(B10="","",INDEX(Resumo_NUTSIII!$I:$I,MATCH(B10,Resumo_NUTSIII!$A:$A,0))) -> 510 | K10: =IF(B10="","",INDEX(Resumo_NUTSIII!$J:$J,MATCH(B10,Resumo_NUTSIII!$A:$A,0))) -> 178 | L10: =IF(B10="","",INDEX(Resumo_NUTSIII!$K:$K,MATCH(B10,Resumo_NUTSIII!$A:$A,0))) -> 5.0
A11: Moura | B11: Baixo Alentejo | C11: =IF(B11="","",INDEX(Resumo_NUTSIII!$B:$B,MATCH(B11,Resumo_NUTSIII!$A:$A,0))) -> 1068 | D11: =IF(B11="","",INDEX(Resumo_NUTSIII!$C:$C,MATCH(B11,Resumo_NUTSIII!$A:$A,0))) -> 10.7 | E11: =IF(B11="","",INDEX(Resumo_NUTSIII!$D:$D,MATCH(B11,Resumo_NUTSIII!$A:$A,0))) -> 24.7 | F11: =IF(B11="","",INDEX(Resumo_NUTSIII!$E:$E,MATCH(B11,Resumo_NUTSIII!$A:$A,0))) -> 155 | G11: =IF(B11="","",INDEX(Resumo_NUTSIII!$F:$F,MATCH(B11,Resumo_NUTSIII!$A:$A,0))) -> 405 | H11: =IF(B11="","",INDEX(Resumo_NUTSIII!$G:$G,MATCH(B11,Resumo_NUTSIII!$A:$A,0))) -> 510 | I11: =IF(B11="","",INDEX(Resumo_NUTSIII!$H:$H,MATCH(B11,Resumo_NUTSIII!$A:$A,0))) -> 225 | J11: =IF(B11="","",INDEX(Resumo_NUTSIII!$I:$I,MATCH(B11,Resumo_NUTSIII!$A:$A,0))) -> 510 | K11: =IF(B11="","",INDEX(Resumo_NUTSIII!$J:$J,MATCH(B11,Resumo_NUTSIII!$A:$A,0))) -> 178 | L11: =IF(B11="","",INDEX(Resumo_NUTSIII!$K:$K,MATCH(B11,Resumo_NUTSIII!$A:$A,0))) -> 5.0
A12: Ourique | B12: Baixo Alentejo | C12: =IF(B12="","",INDEX(Resumo_NUTSIII!$B:$B,MATCH(B12,Resumo_NUTSIII!$A:$A,0))) -> 1068 | D12: =IF(B12="","",INDEX(Resumo_NUTSIII!$C:$C,MATCH(B12,Resumo_NUTSIII!$A:$A,0))) -> 10.7 | E12: =IF(B12="","",INDEX(Resumo_NUTSIII!$D:$D,MATCH(B12,Resumo_NUTSIII!$A:$A,0))) -> 24.7 | F12: =IF(B12="","",INDEX(Resumo_NUTSIII!$E:$E,MATCH(B12,Resumo_NUTSIII!$A:$A,0))) -> 155 | G12: =IF(B12="","",INDEX(Resumo_NUTSIII!$F:$F,MATCH(B12,Resumo_NUTSIII!$A:$A,0))) -> 405 | H12: =IF(B12="","",INDEX(Resumo_NUTSIII!$G:$G,MATCH(B12,Resumo_NUTSIII!$A:$A,0))) -> 510 | I12: =IF(B12="","",INDEX(Resumo_NUTSIII!$H:$H,MATCH(B12,Resumo_NUTSIII!$A:$A,0))) -> 225 | J12: =IF(B12="","",INDEX(Resumo_NUTSIII!$I:$I,MATCH(B12,Resumo_NUTSIII!$A:$A,0))) -> 510 | K12: =IF(B12="","",INDEX(Resumo_NUTSIII!$J:$J,MATCH(B12,Resumo_NUTSIII!$A:$A,0))) -> 178 | L12: =IF(B12="","",INDEX(Resumo_NUTSIII!$K:$K,MATCH(B12,Resumo_NUTSIII!$A:$A,0))) -> 5.0
A13: Serpa | B13: Baixo Alentejo | C13: =IF(B13="","",INDEX(Resumo_NUTSIII!$B:$B,MATCH(B13,Resumo_NUTSIII!$A:$A,0))) -> 1068 | D13: =IF(B13="","",INDEX(Resumo_NUTSIII!$C:$C,MATCH(B13,Resumo_NUTSIII!$A:$A,0))) -> 10.7 | E13: =IF(B13="","",INDEX(Resumo_NUTSIII!$D:$D,MATCH(B13,Resumo_NUTSIII!$A:$A,0))) -> 24.7 | F13: =IF(B13="","",INDEX(Resumo_NUTSIII!$E:$E,MATCH(B13,Resumo_NUTSIII!$A:$A,0))) -> 155 | G13: =IF(B13="","",INDEX(Resumo_NUTSIII!$F:$F,MATCH(B13,Resumo_NUTSIII!$A:$A,0))) -> 405 | H13: =IF(B13="","",INDEX(Resumo_NUTSIII!$G:$G,MATCH(B13,Resumo_NUTSIII!$A:$A,0))) -> 510 | I13: =IF(B13="","",INDEX(Resumo_NUTSIII!$H:$H,MATCH(B13,Resumo_NUTSIII!$A:$A,0))) -> 225 | J13: =IF(B13="","",INDEX(Resumo_NUTSIII!$I:$I,MATCH(B13,Resumo_NUTSIII!$A:$A,0))) -> 510 | K13: =IF(B13="","",INDEX(Resumo_NUTSIII!$J:$J,MATCH(B13,Resumo_NUTSIII!$A:$A,0))) -> 178 | L13: =IF(B13="","",INDEX(Resumo_NUTSIII!$K:$K,MATCH(B13,Resumo_NUTSIII!$A:$A,0))) -> 5.0
A14: Vidigueira | B14: Baixo Alentejo | C14: =IF(B14="","",INDEX(Resumo_NUTSIII!$B:$B,MATCH(B14,Resumo_NUTSIII!$A:$A,0))) -> 1068 | D14: =IF(B14="","",INDEX(Resumo_NUTSIII!$C:$C,MATCH(B14,Resumo_NUTSIII!$A:$A,0))) -> 10.7 | E14: =IF(B14="","",INDEX(Resumo_NUTSIII!$D:$D,MATCH(B14,Resumo_NUTSIII!$A:$A,0))) -> 24.7 | F14: =IF(B14="","",INDEX(Resumo_NUTSIII!$E:$E,MATCH(B14,Resumo_NUTSIII!$A:$A,0))) -> 155 | G14: =IF(B14="","",INDEX(Resumo_NUTSIII!$F:$F,MATCH(B14,Resumo_NUTSIII!$A:$A,0))) -> 405 | H14: =IF(B14="","",INDEX(Resumo_NUTSIII!$G:$G,MATCH(B14,Resumo_NUTSIII!$A:$A,0))) -> 510 | I14: =IF(B14="","",INDEX(Resumo_NUTSIII!$H:$H,MATCH(B14,Resumo_NUTSIII!$A:$A,0))) -> 225 | J14: =IF(B14="","",INDEX(Resumo_NUTSIII!$I:$I,MATCH(B14,Resumo_NUTSIII!$A:$A,0))) -> 510 | K14: =IF(B14="","",INDEX(Resumo_NUTSIII!$J:$J,MATCH(B14,Resumo_NUTSIII!$A:$A,0))) -> 178 | L14: =IF(B14="","",INDEX(Resumo_NUTSIII!$K:$K,MATCH(B14,Resumo_NUTSIII!$A:$A,0))) -> 5.0
L15: =IF(B15="","",INDEX(Resumo_NUTSIII!$K:$K,MATCH(B15,Resumo_NUTSIII!$A:$A,0)))
L16: =IF(B16="","",INDEX(Resumo_NUTSIII!$K:$K,MATCH(B16,Resumo_NUTSIII!$A:$A,0)))
L17: =IF(B17="","",INDEX(Resumo_NUTSIII!$K:$K,MATCH(B17,Resumo_NUTSIII!$A:$A,0)))
L18: =IF(B18="","",INDEX(Resumo_NUTSIII!$K:$K,MATCH(B18,Resumo_NUTSIII!$A:$A,0)))
L19: =IF(B19="","",INDEX(Resumo_NUTSIII!$K:$K,MATCH(B19,Resumo_NUTSIII!$A:$A,0)))
L20: =IF(B20="","",INDEX(Resumo_NUTSIII!$K:$K,MATCH(B20,Resumo_NUTSIII!$A:$A,0)))

Sheet Braga
A1: Concelho | B1: NUTS III | C1: GD_REF | D1: theta_inv_REF | E1: theta_ver_REF | F1: G_inv_sul_kWhm2mes | G1: G_verao_S_kWhm2mes | H1: G_verao_O_kWhm2mes | I1: G_verao_N_kWhm2mes | J1: G_verao_E_kWhm2mes | K1: z_REF_m | L1: Mref
A2: Amares | B2: Cavado | C2: =IF(B2="","",INDEX(Resumo_NUTSIII!$B:$B,MATCH(B2,Resumo_NUTSIII!$A:$A,0))) -> 1491 | D2: =IF(B2="","",INDEX(Resumo_NUTSIII!$C:$C,MATCH(B2,Resumo_NUTSIII!$A:$A,0))) -> 9.0 | E2: =IF(B2="","",INDEX(Resumo_NUTSIII!$D:$D,MATCH(B2,Resumo_NUTSIII!$A:$A,0))) -> 20.7 | F2: =IF(B2="","",INDEX(Resumo_NUTSIII!$E:$E,MATCH(B2,Resumo_NUTSIII!$A:$A,0))) -> 125 | G2: =IF(B2="","",INDEX(Resumo_NUTSIII!$F:$F,MATCH(B2,Resumo_NUTSIII!$A:$A,0))) -> 425 | H2: =IF(B2="","",INDEX(Resumo_NUTSIII!$G:$G,MATCH(B2,Resumo_NUTSIII!$A:$A,0))) -> 485 | I2: =IF(B2="","",INDEX(Resumo_NUTSIII!$H:$H,MATCH(B2,Resumo_NUTSIII!$A:$A,0))) -> 220 | J2: =IF(B2="","",INDEX(Resumo_NUTSIII!$I:$I,MATCH(B2,Resumo_NUTSIII!$A:$A,0))) -> 485 | K2: =IF(B2="","",INDEX(Resumo_NUTSIII!$J:$J,MATCH(B2,Resumo_NUTSIII!$A:$A,0))) -> 171 | L2: =IF(B2="","",INDEX(Resumo_NUTSIII!$K:$K,MATCH(B2,Resumo_NUTSIII!$A:$A,0))) -> 6.8
A3: Barcelos | B3: Cavado | C3: =IF(B3="","",INDEX(Resumo_NUTSIII!$B:$B,MATCH(B3,Resumo_NUTSIII!$A:$A,0))) -> 1491 | D3: =IF(B3="","",INDEX(Resumo_NUTSIII!$C:$C,MATCH(B3,Resumo_NUTSIII!$A:$A,0))) -> 9.0 | E3: =IF(B3="","",INDEX(Resumo_NUTSIII!$D:$D,MATCH(B3,Resumo_NUTSIII!$A:$A,0))) -> 20.7 | F3: =IF(B3="","",INDEX(Resumo_NUTSIII!$E:$E,MATCH(B3,Resumo_NUTSIII!$A:$A,0))) -> 125 | G3: =IF(B3="","",INDEX(Resumo_NUTSIII!$F:$F,MATCH(B3,Resumo_NUTSIII!$A:$A,0))) -> 425 | H3: =IF(B3="","",INDEX(Resumo_NUTSIII!$G:$G,MATCH(B3,Resumo_NUTSIII!$A:$A,0))) -> 485 | I3: =IF(B3="","",INDEX(Resumo_NUTSIII!$H:$H,MATCH(B3,Resumo_NUTSIII!$A:$A,0))) -> 220 | J3: =IF(B3="","",INDEX(Resumo_NUTSIII!$I:$I,MATCH(B3,Resumo_NUTSIII!$A:$A,0))) -> 485 | K3: =IF(B3="","",INDEX(Resumo_NUTSIII!$J:$J,MATCH(B3,Resumo_NUTSIII!$A:$A,0))) -> 171 | L3: =IF(B3="","",INDEX(Resumo_NUTSIII!$K:$K,MATCH(B3,Resumo_NUTSIII!$A:$A,0))) -> 6.8
A4: Braga | B4: Cavado | C4: =IF(B4="","",INDEX(Resumo_NUTSIII!$B:$B,MATCH(B4,Resumo_NUTSIII!$A:$A,0))) -> 1491 | D4: =IF(B4="","",INDEX(Resumo_NUTSIII!$C:$C,MATCH(B4,Resumo_NUTSIII!$A:$A,0))) -> 9.0 | E4: =IF(B4="","",INDEX(Resumo_NUTSIII!$D:$D,MATCH(B4,Resumo_NUTSIII!$A:$A,0))) -> 20.7 | F4: =IF(B4="","",INDEX(Resumo_NUTSIII!$E:$E,MATCH(B4,Resumo_NUTSIII!$A:$A,0))) -> 125 | G4: =IF(B4="","",INDEX(Resumo_NUTSIII!$F:$F,MATCH(B4,Resumo_NUTSIII!$A:$A,0))) -> 425 | H4: =IF(B4="","",INDEX(Resumo_NUTSIII!$G:$G,MATCH(B4,Resumo_NUTSIII!$A:$A,0))) -> 485 | I4: =IF(B4="","",INDEX(Resumo_NUTSIII!$H:$H,MATCH(B4,Resumo_NUTSIII!$A:$A,0))) -> 220 | J4: =IF(B4="","",INDEX(Resumo_NUTSIII!$I:$I,MATCH(B4,Resumo_NUTSIII!$A:$A,0))) -> 485 | K4: =IF(B4="","",INDEX(Resumo_NUTSIII!$J:$J,MATCH(B4,Resumo_NUTSIII!$A:$A,0))) -> 171 | L4: =IF(B4="","",INDEX(Resumo_NUTSIII!$K:$K,MATCH(B4,Resumo_NUTSIII!$A:$A,0))) -> 6.8
A5: Cabeceiras de Basto | B5: Ave | C5: =IF(B5="","",INDEX(Resumo_NUTSIII!$B:$B,MATCH(B5,Resumo_NUTSIII!$A:$A,0))) -> 1653 | D5: =IF(B5="","",INDEX(Resumo_NUTSIII!$C:$C,MATCH(B5,Resumo_NUTSIII!$A:$A,0))) -> 7.8 | E5: =IF(B5="","",INDEX(Resumo_NUTSIII!$D:$D,MATCH(B5,Resumo_NUTSIII!$A:$A,0))) -> 20.8 | F5: =IF(B5="","",INDEX(Resumo_NUTSIII!$E:$E,MATCH(B5,Resumo_NUTSIII!$A:$A,0))) -> 125 | G5: =IF(B5="","",INDEX(Resumo_NUTSIII!$F:$F,MATCH(B5,Resumo_NUTSIII!$A:$A,0))) -> 425 | H5: =IF(B5="","",INDEX(Resumo_NUTSIII!$G:$G,MATCH(B5,Resumo_NUTSIII!$A:$A,0))) -> 490 | I5: =IF(B5="","",INDEX(Resumo_NUTSIII!$H:$H,MATCH(B5,Resumo_NUTSIII!$A:$A,0))) -> 220 | J5: =IF(B5="","",INDEX(Resumo_NUTSIII!$I:$I,MATCH(B5,Resumo_NUTSIII!$A:$A,0))) -> 490 | K5: =IF(B5="","",INDEX(Resumo_NUTSIII!$J:$J,MATCH(B5,Resumo_NUTSIII!$A:$A,0))) -> 426 | L5: =IF(B5="","",INDEX(Resumo_NUTSIII!$K:$K,MATCH(B5,Resumo_NUTSIII!$A:$A,0))) -> 7.2
A6: Celorico de Basto | B6: Ave | C6: =IF(B6="","",INDEX(Resumo_NUTSIII!$B:$B,MATCH(B6,Resumo_NUTSIII!$A:$A,0))) -> 1653 | D6: =IF(B6="","",INDEX(Resumo_NUTSIII!$C:$C,MATCH(B6,Resumo_NUTSIII!$A:$A,0))) -> 7.8 | E6: =IF(B6="","",INDEX(Resumo_NUTSIII!$D:$D,MATCH(B6,Resumo_NUTSIII!$A:$A,0))) -> 20.8 | F6: =IF(B6="","",INDEX(Resumo_NUTSIII!$E:$E,MATCH(B6,Resumo_NUTSIII!$A:$A,0))) -> 125 | G6: =IF(B6="","",INDEX(Resumo_NUTSIII!$F:$F,MATCH(B6,Resumo_NUTSIII!$A:$A,0))) -> 425 | H6: =IF(B6="","",INDEX(Resumo_NUTSIII!$G:$G,MATCH(B6,Resumo_NUTSIII!$A:$A,0))) -> 490 | I6: =IF(B6="","",INDEX(Resumo_NUTSIII!$H:$H,MATCH(B6,Resumo_NUTSIII!$A:$A,0))) -> 220 | J6: =IF(B6="","",INDEX(Resumo_NUTSIII!$I:$I,MATCH(B6,Resumo_NUTSIII!$A:$A,0))) -> 490 | K6: =IF(B6="","",INDEX(Resumo_NUTSIII!$J:$J,MATCH(B6,Resumo_NUTSIII!$A:$A,0))) -> 426 | L6: =IF(B6="","",INDEX(Resumo_NUTSIII!$K:$K,MATCH(B6,Resumo_NUTSIII!$A:$A,0))) -> 7.2
A7: Esposende | B7: Cavado | C7: =IF(B7="","",INDEX(Resumo_NUTSIII!$B:$B,MATCH(B7,Resumo_NUTSIII!$A:$A,0))) -> 1491 | D7: =IF(B7="","",INDEX(Resumo_NUTSIII!$C:$C,MATCH(B7,Resumo_NUTSIII!$A:$A,0))) -> 9.0 | E7: =IF(B7="","",INDEX(Resumo_NUTSIII!$D:$D,MATCH(B7,Resumo_NUTSIII!$A:$A,0))) -> 20.7 | F7: =IF(B7="","",INDEX(Resumo_NUTSIII!$E:$E,MATCH(B7,Resumo_NUTSIII!$A:$A,0))) -> 125 | G7: =IF(B7="","",INDEX(Resumo_NUTSIII!$F:$F,MATCH(B7,Resumo_NUTSIII!$A:$A,0))) -> 425 | H7: =IF(B7="","",INDEX(Resumo_NUTSIII!$G:$G,MATCH(B7,Resumo_NUTSIII!$A:$A,0))) -> 485 | I7: =IF(B7="","",INDEX(Resumo_NUTSIII!$H:$H,MATCH(B7,Resumo_NUTSIII!$A:$A,0))) -> 220 | J7: =IF(B7="","",INDEX(Resumo_NUTSIII!$I:$I,MATCH(B7,Resumo_NUTSIII!$A:$A,0))) -> 485 | K7: =IF(B7="","",INDEX(Resumo_NUTSIII!$J:$J,MATCH(B7,Resumo_NUTSIII!$A:$A,0))) -> 171 | L7: =IF(B7="","",INDEX(Resumo_NUTSIII!$K:$K,MATCH(B7,Resumo_NUTSIII!$A:$A,0))) -> 6.8
A8: Fafe | B8: Ave | C8: =IF(B8="","",INDEX(Resumo_NUTSIII!$B:$B,MATCH(B8,Resumo_NUTSIII!$A:$A,0))) -> 1653 | D8: =IF(B8="","",INDEX(Resumo_NUTSIII!$C:$C,MATCH(B8,Resumo_NUTSIII!$A:$A,0))) -> 7.8 | E8: =IF(B8="","",INDEX(Resumo_NUTSIII!$D:$D,MATCH(B8,Resumo_NUTSIII!$A:$A,0))) -> 20.8 | F8: =IF(B8="","",INDEX(Resumo_NUTSIII!$E:$E,MATCH(B8,Resumo_NUTSIII!$A:$A,0))) -> 125 | G8: =IF(B8="","",INDEX(Resumo_NUTSIII!$F:$F,MATCH(B8,Resumo_NUTSIII!$A:$A,0))) -> 425 | H8: =IF(B8="","",INDEX(Resumo_NUTSIII!$G:$G,MATCH(B8,Resumo_NUTSIII!$A:$A,0))) -> 490 | I8: =IF(B8="","",INDEX(Resumo_NUTSIII!$H:$H,MATCH(B8,Resumo_NUTSIII!$A:$A,0))) -> 220 | J8: =IF(B8="","",INDEX(Resumo_NUTSIII!$I:$I,MATCH(B8,Resumo_NUTSIII!$A:$A,0))) -> 490 | K8: =IF(B8="","",INDEX(Resumo_NUTSIII!$J:$J,MATCH(B8,Resumo_NUTSIII!$A:$A,0))) -> 426 | L8: =IF(B8="","",INDEX(Resumo_NUTSIII!$K:$K,MATCH(B8,Resumo_NUTSIII!$A:$A,0))) -> 7.2
A9: Guimarães | B9: Ave | C9: =IF(B9="","",INDEX(Resumo_NUTSIII!$B:$B,MATCH(B9,Resumo_NUTSIII!$A:$A,0))) -> 1653 | D9: =IF(B9="","",INDEX(Resumo_NUTSIII!$C:$C,MATCH(B9,Resumo_NUTSIII!$A:$A,0))) -> 7.8 | E9: =IF(B9="","",INDEX(Resumo_NUTSIII!$D:$D,MATCH(B9,Resumo_NUTSIII!$A:$A,0))) -> 20.8 | F9: =IF(B9="","",INDEX(Resumo_NUTSIII!$E:$E,MATCH(B9,Resumo_NUTSIII!$A:$A,0))) -> 125 | G9: =IF(B9="","",INDEX(Resumo_NUTSIII!$F:$F,MATCH(B9,Resumo_NUTSIII!$A:$A,0))) -> 425 | H9: =IF(B9="","",INDEX(Resumo_NUTSIII!$G:$G,MATCH(B9,Resumo_NUTSIII!$A:$A,0))) -> 490 | I9: =IF(B9="","",INDEX(Resumo_NUTSIII!$H:$H,MATCH(B9,Resumo_NUTSIII!$A:$A,0))) -> 220 | J9: =IF(B9="","",INDEX(Resumo_NUTSIII!$I:$I,MATCH(B9,Resumo_NUTSIII!$A:$A,0))) -> 490 | K9: =IF(B9="","",INDEX(Resumo_NUTSIII!$J:$J,MATCH(B9,Resumo_NUTSIII!$A:$A,0))) -> 426 | L9: =IF(B9="","",INDEX(Resumo_NUTSIII!$K:$K,MATCH(B9,Resumo_NUTSIII!$A:$A,0))) -> 7.2
A10: Póvoa de Lanhoso | B10: Ave | C10: =IF(B10="","",INDEX(Resumo_NUTSIII!$B:$B,MATCH(B10,Resumo_NUTSIII!$A:$A,0))) -> 1653 | D10: =IF(B10="","",INDEX(Resumo_NUTSIII!$C:$C,MATCH(B10,Resumo_NUTSIII!$A:$A,0))) -> 7.8 | E10: =IF(B10="","",INDEX(Resumo_NUTSIII!$D:$D,MATCH(B10,Resumo_NUTSIII!$A:$A,0))) -> 20.8 | F10: =IF(B10="","",INDEX(Resumo_NUTSIII!$E:$E,MATCH(B10,Resumo_NUTSIII!$A:$A,0))) -> 125 | G10: =IF(B10="","",INDEX(Resumo_NUTSIII!$F:$F,MATCH(B10,Resumo_NUTSIII!$A:$A,0))) -> 425 | H10: =IF(B10="","",INDEX(Resumo_NUTSIII!$G:$G,MATCH(B10,Resumo_NUTSIII!$A:$A,0))) -> 490 | I10: =IF(B10="","",INDEX(Resumo_NUTSIII!$H:$H,MATCH(B10,Resumo_NUTSIII!$A:$A,0))) -> 220 | J10: =IF(B10="","",INDEX(Resumo_NUTSIII!$I:$I,MATCH(B10,Resumo_NUTSIII!$A:$A,0))) -> 490 | K10: =IF(B10="","",INDEX(Resumo_NUTSIII!$J:$J,MATCH(B10,Resumo_NUTSIII!$A:$A,0))) -> 426 | L10: =IF(B10="","",INDEX(Resumo_NUTSIII!$K:$K,MATCH(B10,Resumo_NUTSIII!$A:$A,0))) -> 7.2
A11: Terras de Bouro | B11: Cavado | C11: =IF(B11="","",INDEX(Resumo_NUTSIII!$B:$B,MATCH(B11,Resumo_NUTSIII!$A:$A,0))) -> 1491 | D11: =IF(B11="","",INDEX(Resumo_NUTSIII!$C:$C,MATCH(B11,Resumo_NUTSIII!$A:$A,0))) -> 9.0 | E11: =IF(B11="","",INDEX(Resumo_NUTSIII!$D:$D,MATCH(B11,Resumo_NUTSIII!$A:$A,0))) -> 20.7 | F11: =IF(B11="","",INDEX(Resumo_NUTSIII!$E:$E,MATCH(B11,Resumo_NUTSIII!$A:$A,0))) -> 125 | G11: =IF(B11="","",INDEX(Resumo_NUTSIII!$F:$F,MATCH(B11,Resumo_NUTSIII!$A:$A,0))) -> 425 | H11: =IF(B11="","",INDEX(Resumo_NUTSIII!$G:$G,MATCH(B11,Resumo_NUTSIII!$A:$A,0))) -> 485 | I11: =IF(B11="","",INDEX(Resumo_NUTSIII!$H:$H,MATCH(B11,Resumo_NUTSIII!$A:$A,0))) -> 220 | J11: =IF(B11="","",INDEX(Resumo_NUTSIII!$I:$I,MATCH(B11,Resumo_NUTSIII!$A:$A,0))) -> 485 | K11: =IF(B11="","",INDEX(Resumo_NUTSIII!$J:$J,MATCH(B11,Resumo_NUTSIII!$A:$A,0))) -> 171 | L11: =IF(B11="","",INDEX(Resumo_NUTSIII!$K:$K,MATCH(B11,Resumo_NUTSIII!$A:$A,0))) -> 6.8
A12: Vieira do Minho | B12: Ave | C12: =IF(B12="","",INDEX(Resumo_NUTSIII!$B:$B,MATCH(B12,Resumo_NUTSIII!$A:$A,0))) -> 1653 | D12: =IF(B12="","",INDEX(Resumo_NUTSIII!$C:$C,MATCH(B12,Resumo_NUTSIII!$A:$A,0))) -> 7.8 | E12: =IF(B12="","",INDEX(Resumo_NUTSIII!$D:$D,MATCH(B12,Resumo_NUTSIII!$A:$A,0))) -> 20.8 | F12: =IF(B12="","",INDEX(Resumo_NUTSIII!$E:$E,MATCH(B12,Resumo_NUTSIII!$A:$A,0))) -> 125 | G12: =IF(B12="","",INDEX(Resumo_NUTSIII!$F:$F,MATCH(B12,Resumo_NUTSIII!$A:$A,0))) -> 425 | H12: =IF(B12="","",INDEX(Resumo_NUTSIII!$G:$G,MATCH(B12,Resumo_NUTSIII!$A:$A,0))) -> 490 | I12: =IF(B12="","",INDEX(Resumo_NUTSIII!$H:$H,MATCH(B12,Resumo_NUTSIII!$A:$A,0))) -> 220 | J12: =IF(B12="","",INDEX(Resumo_NUTSIII!$I:$I,MATCH(B12,Resumo_NUTSIII!$A:$A,0))) -> 490 | K12: =IF(B12="","",INDEX(Resumo_NUTSIII!$J:$J,MATCH(B12,Resumo_NUTSIII!$A:$A,0))) -> 426 | L12: =IF(B12="","",INDEX(Resumo_NUTSIII!$K:$K,MATCH(B12,Resumo_NUTSIII!$A:$A,0))) -> 7.2
A13: Vila Nova de Famalicão | B13: Ave | C13: =IF(B13="","",INDEX(Resumo_NUTSIII!$B:$B,MATCH(B13,Resumo_NUTSIII!$A:$A,0))) -> 1653 | D13: =IF(B13="","",INDEX(Resumo_NUTSIII!$C:$C,MATCH(B13,Resumo_NUTSIII!$A:$A,0))) -> 7.8 | E13: =IF(B13="","",INDEX(Resumo_NUTSIII!$D:$D,MATCH(B13,Resumo_NUTSIII!$A:$A,0))) -> 20.8 | F13: =IF(B13="","",INDEX(Resumo_NUTSIII!$E:$E,MATCH(B13,Resumo_NUTSIII!$A:$A,0))) -> 125 | G13: =IF(B13="","",INDEX(Resumo_NUTSIII!$F:$F,MATCH(B13,Resumo_NUTSIII!$A:$A,0))) -> 425 | H13: =IF(B13="","",INDEX(Resumo_NUTSIII!$G:$G,MATCH(B13,Resumo_NUTSIII!$A:$A,0))) -> 490 | I13: =IF(B13="","",INDEX(Resumo_NUTSIII!$H:$H,MATCH(B13,Resumo_NUTSIII!$A:$A,0))) -> 220 | J13: =IF(B13="","",INDEX(Resumo_NUTSIII!$I:$I,MATCH(B13,Resumo_NUTSIII!$A:$A,0))) -> 490 | K13: =IF(B13="","",INDEX(Resumo_NUTSIII!$J:$J,MATCH(B13,Resumo_NUTSIII!$A:$A,0))) -> 426 | L13: =IF(B13="","",INDEX(Resumo_NUTSIII!$K:$K,MATCH(B13,Resumo_NUTSIII!$A:$A,0))) -> 7.2
... A15: Vizela | B15: Ave | C15: =IF(B15="","",INDEX(Resumo_NUTSIII!$B:$B,MATCH(B15,Resumo_NUTSIII!$A:$A,0))) -> 1653 | D15: =IF(B15="","",INDEX(Resumo_NUTSIII!$C:$C,MATCH(B15,Resumo_NUTSIII!$A:$A,0))) -> 7.8 | E15: =IF(B15="","",INDEX(Resumo_NUTSIII!$D:$D,MATCH(B15,Resumo_NUTSIII!$A:$A,0))) -> 20.8 | F15: =IF(B15="","",INDEX(Resumo_NUTSIII!$E:$E,MATCH(B15,Resumo_NUTSIII!$A:$A,0))) -> 125 | G15: =IF(B15="","",INDEX(Resumo_NUTSIII!$F:$F,MATCH(B15,Resumo_NUTSIII!$A:$A,0))) -> 425 | H15: =IF(B15="","",INDEX(Resumo_NUTSIII!$G:$G,MATCH(B15,Resumo_NUTSIII!$A:$A,0))) -> 490 | I15: =IF(B15="","",INDEX(Resumo_NUTSIII!$H:$H,MATCH(B15,Resumo_NUTSIII!$A:$A,0))) -> 220 | J15: =IF(B15="","",INDEX(Resumo_NUTSIII!$I:$I,MATCH(B15,Resumo_NUTSIII!$A:$A,0))) -> 490 | K15: =IF(B15="","",INDEX(Resumo_NUTSIII!$J:$J,MATCH(B15,Resumo_NUTSIII!$A:$A,0))) -> 426 | L15: =IF(B15="","",INDEX(Resumo_NUTSIII!$K:$K,MATCH(B15,Resumo_NUTSIII!$A:$A,0))) -> 7.2
L16: =IF(B16="","",INDEX(Resumo_NUTSIII!$K:$K,MATCH(B16,Resumo_NUTSIII!$A:$A,0)))
L17: =IF(B17="","",INDEX(Resumo_NUTSIII!$K:$K,MATCH(B17,Resumo_NUTSIII!$A:$A,0)))
L18: =IF(B18="","",INDEX(Resumo_NUTSIII!$K:$K,MATCH(B18,Resumo_NUTSIII!$A:$A,0)))
L19: =IF(B19="","",INDEX(Resumo_NUTSIII!$K:$K,MATCH(B19,Resumo_NUTSIII!$A:$A,0)))
L20: =IF(B20="","",INDEX(Resumo_NUTSIII!$K:$K,MATCH(B20,Resumo_NUTSIII!$A:$A,0)))

Sheet Braganca
A1: Concelho | B1: NUTS III | C1: GD_REF | D1: theta_inv_REF | E1: theta_ver_REF | F1: G_inv_sul_kWhm2mes | G1: G_verao_S_kWhm2mes | H1: G_verao_O_kWhm2mes | I1: G_verao_N_kWhm2mes | J1: G_verao_E_kWhm2mes | K1: z_REF_m | L1: Mref
A2: Alfândega da Fé | B2: Alto Tras-os-Montes | C2: =IF(B2="","",INDEX(Resumo_NUTSIII!$B:$B,MATCH(B2,Resumo_NUTSIII!$A:$A,0))) -> 2015 | D2: =IF(B2="","",INDEX(Resumo_NUTSIII!$C:$C,MATCH(B2,Resumo_NUTSIII!$A:$A,0))) -> 5.5 | E2: =IF(B2="","",INDEX(Resumo_NUTSIII!$D:$D,MATCH(B2,Resumo_NUTSIII!$A:$A,0))) -> 21.5 | F2: =IF(B2="","",INDEX(Resumo_NUTSIII!$E:$E,MATCH(B2,Resumo_NUTSIII!$A:$A,0))) -> 125 | G2: =IF(B2="","",INDEX(Resumo_NUTSIII!$F:$F,MATCH(B2,Resumo_NUTSIII!$A:$A,0))) -> 425 | H2: =IF(B2="","",INDEX(Resumo_NUTSIII!$G:$G,MATCH(B2,Resumo_NUTSIII!$A:$A,0))) -> 480 | I2: =IF(B2="","",INDEX(Resumo_NUTSIII!$H:$H,MATCH(B2,Resumo_NUTSIII!$A:$A,0))) -> 220 | J2: =IF(B2="","",INDEX(Resumo_NUTSIII!$I:$I,MATCH(B2,Resumo_NUTSIII!$A:$A,0))) -> 480 | K2: =IF(B2="","",INDEX(Resumo_NUTSIII!$J:$J,MATCH(B2,Resumo_NUTSIII!$A:$A,0))) -> 680 | L2: =IF(B2="","",INDEX(Resumo_NUTSIII!$K:$K,MATCH(B2,Resumo_NUTSIII!$A:$A,0))) -> 7.3
A3: Bragança | B3: Alto Tras-os-Montes | C3: =IF(B3="","",INDEX(Resumo_NUTSIII!$B:$B,MATCH(B3,Resumo_NUTSIII!$A:$A,0))) -> 2015 | D3: 5.5 | E3: =IF(B3="","",INDEX(Resumo_NUTSIII!$D:$D,MATCH(B3,Resumo_NUTSIII!$A:$A,0))) -> 21.5 | F3: =IF(B3="","",INDEX(Resumo_NUTSIII!$E:$E,MATCH(B3,Resumo_NUTSIII!$A:$A,0))) -> 125 | G3: =IF(B3="","",INDEX(Resumo_NUTSIII!$F:$F,MATCH(B3,Resumo_NUTSIII!$A:$A,0))) -> 425 | H3: =IF(B3="","",INDEX(Resumo_NUTSIII!$G:$G,MATCH(B3,Resumo_NUTSIII!$A:$A,0))) -> 480 | I3: =IF(B3="","",INDEX(Resumo_NUTSIII!$H:$H,MATCH(B3,Resumo_NUTSIII!$A:$A,0))) -> 220 | J3: =IF(B3="","",INDEX(Resumo_NUTSIII!$I:$I,MATCH(B3,Resumo_NUTSIII!$A:$A,0))) -> 480 | K3: =IF(B3="","",INDEX(Resumo_NUTSIII!$J:$J,MATCH(B3,Resumo_NUTSIII!$A:$A,0))) -> 680 | L3: =IF(B3="","",INDEX(Resumo_NUTSIII!$K:$K,MATCH(B3,Resumo_NUTSIII!$A:$A,0))) -> 7.3
A4: Carrazeda de Ansiães | B4: Douro | C4: =IF(B4="","",INDEX(Resumo_NUTSIII!$B:$B,MATCH(B4,Resumo_NUTSIII!$A:$A,0))) -> 1764 | D4: 6.3 | E4: =IF(B4="","",INDEX(Resumo_NUTSIII!$D:$D,MATCH(B4,Resumo_NUTSIII!$A:$A,0))) -> 22.7 | F4: =IF(B4="","",INDEX(Resumo_NUTSIII!$E:$E,MATCH(B4,Resumo_NUTSIII!$A:$A,0))) -> 135 | G4: =IF(B4="","",INDEX(Resumo_NUTSIII!$F:$F,MATCH(B4,Resumo_NUTSIII!$A:$A,0))) -> 420 | H4: =IF(B4="","",INDEX(Resumo_NUTSIII!$G:$G,MATCH(B4,Resumo_NUTSIII!$A:$A,0))) -> 490 | I4: =IF(B4="","",INDEX(Resumo_NUTSIII!$H:$H,MATCH(B4,Resumo_NUTSIII!$A:$A,0))) -> 220 | J4: =IF(B4="","",INDEX(Resumo_NUTSIII!$I:$I,MATCH(B4,Resumo_NUTSIII!$A:$A,0))) -> 490 | K4: =IF(B4="","",INDEX(Resumo_NUTSIII!$J:$J,MATCH(B4,Resumo_NUTSIII!$A:$A,0))) -> 579 | L4: =IF(B4="","",INDEX(Resumo_NUTSIII!$K:$K,MATCH(B4,Resumo_NUTSIII!$A:$A,0))) -> 6.9
A5: Freixo de Espada à Cinta | B5: Douro | C5: =IF(B5="","",INDEX(Resumo_NUTSIII!$B:$B,MATCH(B5,Resumo_NUTSIII!$A:$A,0))) -> 1764 | D5: 6.3 | E5: =IF(B5="","",INDEX(Resumo_NUTSIII!$D:$D,MATCH(B5,Resumo_NUTSIII!$A:$A,0))) -> 22.7 | F5: =IF(B5="","",INDEX(Resumo_NUTSIII!$E:$E,MATCH(B5,Resumo_NUTSIII!$A:$A,0))) -> 135 | G5: =IF(B5="","",INDEX(Resumo_NUTSIII!$F:$F,MATCH(B5,Resumo_NUTSIII!$A:$A,0))) -> 420 | H5: =IF(B5="","",INDEX(Resumo_NUTSIII!$G:$G,MATCH(B5,Resumo_NUTSIII!$A:$A,0))) -> 490 | I5: =IF(B5="","",INDEX(Resumo_NUTSIII!$H:$H,MATCH(B5,Resumo_NUTSIII!$A:$A,0))) -> 220 | J5: =IF(B5="","",INDEX(Resumo_NUTSIII!$I:$I,MATCH(B5,Resumo_NUTSIII!$A:$A,0))) -> 490 | K5: =IF(B5="","",INDEX(Resumo_NUTSIII!$J:$J,MATCH(B5,Resumo_NUTSIII!$A:$A,0))) -> 579 | L5: =IF(B5="","",INDEX(Resumo_NUTSIII!$K:$K,MATCH(B5,Resumo_NUTSIII!$A:$A,0))) -> 6.9
A6: Macedo de Cavaleiros | B6: Alto Tras-os-Montes | C6: =IF(B6="","",INDEX(Resumo_NUTSIII!$B:$B,MATCH(B6,Resumo_NUTSIII!$A:$A,0))) -> 2015 | D6: 5.5 | E6: =IF(B6="","",INDEX(Resumo_NUTSIII!$D:$D,MATCH(B6,Resumo_NUTSIII!$A:$A,0))) -> 21.5 | F6: =IF(B6="","",INDEX(Resumo_NUTSIII!$E:$E,MATCH(B6,Resumo_NUTSIII!$A:$A,0))) -> 125 | G6: =IF(B6="","",INDEX(Resumo_NUTSIII!$F:$F,MATCH(B6,Resumo_NUTSIII!$A:$A,0))) -> 425 | H6: =IF(B6="","",INDEX(Resumo_NUTSIII!$G:$G,MATCH(B6,Resumo_NUTSIII!$A:$A,0))) -> 480 | I6: =IF(B6="","",INDEX(Resumo_NUTSIII!$H:$H,MATCH(B6,Resumo_NUTSIII!$A:$A,0))) -> 220 | J6: =IF(B6="","",INDEX(Resumo_NUTSIII!$I:$I,MATCH(B6,Resumo_NUTSIII!$A:$A,0))) -> 480 | K6: =IF(B6="","",INDEX(Resumo_NUTSIII!$J:$J,MATCH(B6,Resumo_NUTSIII!$A:$A,0))) -> 680 | L6: =IF(B6="","",INDEX(Resumo_NUTSIII!$K:$K,MATCH(B6,Resumo_NUTSIII!$A:$A,0))) -> 7.3
A7: Miranda do Douro | B7: Alto Tras-os-Montes | C7: =IF(B7="","",INDEX(Resumo_NUTSIII!$B:$B,MATCH(B7,Resumo_NUTSIII!$A:$A,0))) -> 2015 | D7: 5.5 | E7: =IF(B7="","",INDEX(Resumo_NUTSIII!$D:$D,MATCH(B7,Resumo_NUTSIII!$A:$A,0))) -> 21.5 | F7: =IF(B7="","",INDEX(Resumo_NUTSIII!$E:$E,MATCH(B7,Resumo_NUTSIII!$A:$A,0))) -> 125 | G7: =IF(B7="","",INDEX(Resumo_NUTSIII!$F:$F,MATCH(B7,Resumo_NUTSIII!$A:$A,0))) -> 425 | H7: =IF(B7="","",INDEX(Resumo_NUTSIII!$G:$G,MATCH(B7,Resumo_NUTSIII!$A:$A,0))) -> 480 | I7: =IF(B7="","",INDEX(Resumo_NUTSIII!$H:$H,MATCH(B7,Resumo_NUTSIII!$A:$A,0))) -> 220 | J7: =IF(B7="","",INDEX(Resumo_NUTSIII!$I:$I,MATCH(B7,Resumo_NUTSIII!$A:$A,0))) -> 480 | K7: =IF(B7="","",INDEX(Resumo_NUTSIII!$J:$J,MATCH(B7,Resumo_NUTSIII!$A:$A,0))) -> 680 | L7: =IF(B7="","",INDEX(Resumo_NUTSIII!$K:$K,MATCH(B7,Resumo_NUTSIII!$A:$A,0))) -> 7.3
A8: Mirandela | B8: Alto Tras-os-Montes | C8: =IF(B8="","",INDEX(Resumo_NUTSIII!$B:$B,MATCH(B8,Resumo_NUTSIII!$A:$A,0))) -> 2015 | D8: 5.5 | E8: =IF(B8="","",INDEX(Resumo_NUTSIII!$D:$D,MATCH(B8,Resumo_NUTSIII!$A:$A,0))) -> 21.5 | F8: =IF(B8="","",INDEX(Resumo_NUTSIII!$E:$E,MATCH(B8,Resumo_NUTSIII!$A:$A,0))) -> 125 | G8: =IF(B8="","",INDEX(Resumo_NUTSIII!$F:$F,MATCH(B8,Resumo_NUTSIII!$A:$A,0))) -> 425 | H8: =IF(B8="","",INDEX(Resumo_NUTSIII!$G:$G,MATCH(B8,Resumo_NUTSIII!$A:$A,0))) -> 480 | I8: =IF(B8="","",INDEX(Resumo_NUTSIII!$H:$H,MATCH(B8,Resumo_NUTSIII!$A:$A,0))) -> 220 | J8: =IF(B8="","",INDEX(Resumo_NUTSIII!$I:$I,MATCH(B8,Resumo_NUTSIII!$A:$A,0))) -> 480 | K8: =IF(B8="","",INDEX(Resumo_NUTSIII!$J:$J,MATCH(B8,Resumo_NUTSIII!$A:$A,0))) -> 680 | L8: =IF(B8="","",INDEX(Resumo_NUTSIII!$K:$K,MATCH(B8,Resumo_NUTSIII!$A:$A,0))) -> 7.3
A9: Mogadouro | B9: Alto Tras-os-Montes | C9: =IF(B9="","",INDEX(Resumo_NUTSIII!$B:$B,MATCH(B9,Resumo_NUTSIII!$A:$A,0))) -> 2015 | D9: 5.5 | E9: =IF(B9="","",INDEX(Resumo_NUTSIII!$D:$D,MATCH(B9,Resumo_NUTSIII!$A:$A,0))) -> 21.5 | F9: =IF(B9="","",INDEX(Resumo_NUTSIII!$E:$E,MATCH(B9,Resumo_NUTSIII!$A:$A,0))) -> 125 | G9: =IF(B9="","",INDEX(Resumo_NUTSIII!$F:$F,MATCH(B9,Resumo_NUTSIII!$A:$A,0))) -> 425 | H9: =IF(B9="","",INDEX(Resumo_NUTSIII!$G:$G,MATCH(B9,Resumo_NUTSIII!$A:$A,0))) -> 480 | I9: =IF(B9="","",INDEX(Resumo_NUTSIII!$H:$H,MATCH(B9,Resumo_NUTSIII!$A:$A,0))) -> 220 | J9: =IF(B9="","",INDEX(Resumo_NUTSIII!$I:$I,MATCH(B9,Resumo_NUTSIII!$A:$A,0))) -> 480 | K9: =IF(B9="","",INDEX(Resumo_NUTSIII!$J:$J,MATCH(B9,Resumo_NUTSIII!$A:$A,0))) -> 680 | L9: =IF(B9="","",INDEX(Resumo_NUTSIII!$K:$K,MATCH(B9,Resumo_NUTSIII!$A:$A,0))) -> 7.3
A10: Torre de Moncorvo | B10: Douro | C10: =IF(B10="","",INDEX(Resumo_NUTSIII!$B:$B,MATCH(B10,Resumo_NUTSIII!$A:$A,0))) -> 1764 | D10: 6.3 | E10: =IF(B10="","",INDEX(Resumo_NUTSIII!$D:$D,MATCH(B10,Resumo_NUTSIII!$A:$A,0))) -> 22.7 | F10: =IF(B10="","",INDEX(Resumo_NUTSIII!$E:$E,MATCH(B10,Resumo_NUTSIII!$A:$A,0))) -> 135 | G10: =IF(B10="","",INDEX(Resumo_NUTSIII!$F:$F,MATCH(B10,Resumo_NUTSIII!$A:$A,0))) -> 420 | H10: =IF(B10="","",INDEX(Resumo_NUTSIII!$G:$G,MATCH(B10,Resumo_NUTSIII!$A:$A,0))) -> 490 | I10: =IF(B10="","",INDEX(Resumo_NUTSIII!$H:$H,MATCH(B10,Resumo_NUTSIII!$A:$A,0))) -> 220 | J10: =IF(B10="","",INDEX(Resumo_NUTSIII!$I:$I,MATCH(B10,Resumo_NUTSIII!$A:$A,0))) -> 490 | K10: =IF(B10="","",INDEX(Resumo_NUTSIII!$J:$J,MATCH(B10,Resumo_NUTSIII!$A:$A,0))) -> 579 | L10: =IF(B10="","",INDEX(Resumo_NUTSIII!$K:$K,MATCH(B10,Resumo_NUTSIII!$A:$A,0))) -> 6.9
A11: Vila Flor | B11: Alto Tras-os-Montes | C11: =IF(B11="","",INDEX(Resumo_NUTSIII!$B:$B,MATCH(B11,Resumo_NUTSIII!$A:$A,0))) -> 2015 | D11: 5.5 | E11: =IF(B11="","",INDEX(Resumo_NUTSIII!$D:$D,MATCH(B11,Resumo_NUTSIII!$A:$A,0))) -> 21.5 | F11: =IF(B11="","",INDEX(Resumo_NUTSIII!$E:$E,MATCH(B11,Resumo_NUTSIII!$A:$A,0))) -> 125 | G11: =IF(B11="","",INDEX(Resumo_NUTSIII!$F:$F,MATCH(B11,Resumo_NUTSIII!$A:$A,0))) -> 425 | H11: =IF(B11="","",INDEX(Resumo_NUTSIII!$G:$G,MATCH(B11,Resumo_NUTSIII!$A:$A,0))) -> 480 | I11: =IF(B11="","",INDEX(Resumo_NUTSIII!$H:$H,MATCH(B11,Resumo_NUTSIII!$A:$A,0))) -> 220 | J11: =IF(B11="","",INDEX(Resumo_NUTSIII!$I:$I,MATCH(B11,Resumo_NUTSIII!$A:$A,0))) -> 480 | K11: =IF(B11="","",INDEX(Resumo_NUTSIII!$J:$J,MATCH(B11,Resumo_NUTSIII!$A:$A,0))) -> 680 | L11: =IF(B11="","",INDEX(Resumo_NUTSIII!$K:$K,MATCH(B11,Resumo_NUTSIII!$A:$A,0))) -> 7.3
A12: Vila Nova de Foz Côa | B12: Douro | C12: =IF(B12="","",INDEX(Resumo_NUTSIII!$B:$B,MATCH(B12,Resumo_NUTSIII!$A:$A,0))) -> 1764 | D12: 6.3 | E12: =IF(B12="","",INDEX(Resumo_NUTSIII!$D:$D,MATCH(B12,Resumo_NUTSIII!$A:$A,0))) -> 22.7 | F12: =IF(B12="","",INDEX(Resumo_NUTSIII!$E:$E,MATCH(B12,Resumo_NUTSIII!$A:$A,0))) -> 135 | G12: =IF(B12="","",INDEX(Resumo_NUTSIII!$F:$F,MATCH(B12,Resumo_NUTSIII!$A:$A,0))) -> 420 | H12: =IF(B12="","",INDEX(Resumo_NUTSIII!$G:$G,MATCH(B12,Resumo_NUTSIII!$A:$A,0))) -> 490 | I12: =IF(B12="","",INDEX(Resumo_NUTSIII!$H:$H,MATCH(B12,Resumo_NUTSIII!$A:$A,0))) -> 220 | J12: =IF(B12="","",INDEX(Resumo_NUTSIII!$I:$I,MATCH(B12,Resumo_NUTSIII!$A:$A,0))) -> 490 | K12: =IF(B12="","",INDEX(Resumo_NUTSIII!$J:$J,MATCH(B12,Resumo_NUTSIII!$A:$A,0))) -> 579 | L12: =IF(B12="","",INDEX(Resumo_NUTSIII!$K:$K,MATCH(B12,Resumo_NUTSIII!$A:$A,0))) -> 6.9
A13: Vimioso | B13: Alto Tras-os-Montes | C13: =IF(B13="","",INDEX(Resumo_NUTSIII!$B:$B,MATCH(B13,Resumo_NUTSIII!$A:$A,0))) -> 2015 | D13: 5.5 | E13: =IF(B13="","",INDEX(Resumo_NUTSIII!$D:$D,MATCH(B13,Resumo_NUTSIII!$A:$A,0))) -> 21.5 | F13: =IF(B13="","",INDEX(Resumo_NUTSIII!$E:$E,MATCH(B13,Resumo_NUTSIII!$A:$A,0))) -> 125 | G13: =IF(B13="","",INDEX(Resumo_NUTSIII!$F:$F,MATCH(B13,Resumo_NUTSIII!$A:$A,0))) -> 425 | H13: =IF(B13="","",INDEX(Resumo_NUTSIII!$G:$G,MATCH(B13,Resumo_NUTSIII!$A:$A,0))) -> 480 | I13: =IF(B13="","",INDEX(Resumo_NUTSIII!$H:$H,MATCH(B13,Resumo_NUTSIII!$A:$A,0))) -> 220 | J13: =IF(B13="","",INDEX(Resumo_NUTSIII!$I:$I,MATCH(B13,Resumo_NUTSIII!$A:$A,0))) -> 480 | K13: =IF(B13="","",INDEX(Resumo_NUTSIII!$J:$J,MATCH(B13,Resumo_NUTSIII!$A:$A,0))) -> 680 | L13: =IF(B13="","",INDEX(Resumo_NUTSIII!$K:$K,MATCH(B13,Resumo_NUTSIII!$A:$A,0))) -> 7.3
A14: Vinhais | B14: Alto Tras-os-Montes | C14: =IF(B14="","",INDEX(Resumo_NUTSIII!$B:$B,MATCH(B14,Resumo_NUTSIII!$A:$A,0))) -> 2015 | D14: 5.5 | E14: =IF(B14="","",INDEX(Resumo_NUTSIII!$D:$D,MATCH(B14,Resumo_NUTSIII!$A:$A,0))) -> 21.5 | F14: =IF(B14="","",INDEX(Resumo_NUTSIII!$E:$E,MATCH(B14,Resumo_NUTSIII!$A:$A,0))) -> 125 | G14: =IF(B14="","",INDEX(Resumo_NUTSIII!$F:$F,MATCH(B14,Resumo_NUTSIII!$A:$A,0))) -> 425 | H14: =IF(B14="","",INDEX(Resumo_NUTSIII!$G:$G,MATCH(B14,Resumo_NUTSIII!$A:$A,0))) -> 480 | I14: =IF(B14="","",INDEX(Resumo_NUTSIII!$H:$H,MATCH(B14,Resumo_NUTSIII!$A:$A,0))) -> 220 | J14: =IF(B14="","",INDEX(Resumo_NUTSIII!$I:$I,MATCH(B14,Resumo_NUTSIII!$A:$A,0))) -> 480 | K14: =IF(B14="","",INDEX(Resumo_NUTSIII!$J:$J,MATCH(B14,Resumo_NUTSIII!$A:$A,0))) -> 680 | L14: =IF(B14="","",INDEX(Resumo_NUTSIII!$K:$K,MATCH(B14,Resumo_NUTSIII!$A:$A,0))) -> 7.3
L15: =IF(B15="","",INDEX(Resumo_NUTSIII!$K:$K,MATCH(B15,Resumo_NUTSIII!$A:$A,0)))
L16: =IF(B16="","",INDEX(Resumo_NUTSIII!$K:$K,MATCH(B16,Resumo_NUTSIII!$A:$A,0)))
L17: =IF(B17="","",INDEX(Resumo_NUTSIII!$K:$K,MATCH(B17,Resumo_NUTSIII!$A:$A,0)))
L18: =IF(B18="","",INDEX(Resumo_NUTSIII!$K:$K,MATCH(B18,Resumo_NUTSIII!$A:$A,0)))
L19: =IF(B19="","",INDEX(Resumo_NUTSIII!$K:$K,MATCH(B19,Resumo_NUTSIII!$A:$A,0)))
L20: =IF(B20="","",INDEX(Resumo_NUTSIII!$K:$K,MATCH(B20,Resumo_NUTSIII!$A:$A,0)))

Sheet Castelo Branco
A1: Concelho | B1: NUTS III | C1: GD_REF | D1: theta_inv_REF | E1: theta_ver_REF | F1: G_inv_sul_kWhm2mes | G1: G_verao_S_kWhm2mes | H1: G_verao_O_kWhm2mes | I1: G_verao_N_kWhm2mes | J1: G_verao_E_kWhm2mes | K1: z_REF_m | L1: Mref
A2: Belmonte | B2: Cova da Beira | C2: =IF(B2="","",INDEX(Resumo_NUTSIII!$B:$B,MATCH(B2,Resumo_NUTSIII!$A:$A,0))) -> 1687 | D2: =IF(B2="","",INDEX(Resumo_NUTSIII!$C:$C,MATCH(B2,Resumo_NUTSIII!$A:$A,0))) -> 7.5 | E2: =IF(B2="","",INDEX(Resumo_NUTSIII!$D:$D,MATCH(B2,Resumo_NUTSIII!$A:$A,0))) -> 22.5 | F2: =IF(B2="","",INDEX(Resumo_NUTSIII!$E:$E,MATCH(B2,Resumo_NUTSIII!$A:$A,0))) -> 140 | G2: =IF(B2="","",INDEX(Resumo_NUTSIII!$F:$F,MATCH(B2,Resumo_NUTSIII!$A:$A,0))) -> 425 | H2: =IF(B2="","",INDEX(Resumo_NUTSIII!$G:$G,MATCH(B2,Resumo_NUTSIII!$A:$A,0))) -> 495 | I2: =IF(B2="","",INDEX(Resumo_NUTSIII!$H:$H,MATCH(B2,Resumo_NUTSIII!$A:$A,0))) -> 225 | J2: =IF(B2="","",INDEX(Resumo_NUTSIII!$I:$I,MATCH(B2,Resumo_NUTSIII!$A:$A,0))) -> 495 | K2: =IF(B2="","",INDEX(Resumo_NUTSIII!$J:$J,MATCH(B2,Resumo_NUTSIII!$A:$A,0))) -> 507 | L2: =IF(B2="","",INDEX(Resumo_NUTSIII!$K:$K,MATCH(B2,Resumo_NUTSIII!$A:$A,0))) -> 7.1
A3: Castelo Branco | B3: Beira Interior Sul | C3: =IF(B3="","",INDEX(Resumo_NUTSIII!$B:$B,MATCH(B3,Resumo_NUTSIII!$A:$A,0))) -> 1274 | D3: =IF(B3="","",INDEX(Resumo_NUTSIII!$C:$C,MATCH(B3,Resumo_NUTSIII!$A:$A,0))) -> 9.1 | E3: =IF(B3="","",INDEX(Resumo_NUTSIII!$D:$D,MATCH(B3,Resumo_NUTSIII!$A:$A,0))) -> 25.3 | F3: =IF(B3="","",INDEX(Resumo_NUTSIII!$E:$E,MATCH(B3,Resumo_NUTSIII!$A:$A,0))) -> 140 | G3: =IF(B3="","",INDEX(Resumo_NUTSIII!$F:$F,MATCH(B3,Resumo_NUTSIII!$A:$A,0))) -> 420 | H3: =IF(B3="","",INDEX(Resumo_NUTSIII!$G:$G,MATCH(B3,Resumo_NUTSIII!$A:$A,0))) -> 500 | I3: =IF(B3="","",INDEX(Resumo_NUTSIII!$H:$H,MATCH(B3,Resumo_NUTSIII!$A:$A,0))) -> 220 | J3: =IF(B3="","",INDEX(Resumo_NUTSIII!$I:$I,MATCH(B3,Resumo_NUTSIII!$A:$A,0))) -> 500 | K3: =IF(B3="","",INDEX(Resumo_NUTSIII!$J:$J,MATCH(B3,Resumo_NUTSIII!$A:$A,0))) -> 328 | L3: =IF(B3="","",INDEX(Resumo_NUTSIII!$K:$K,MATCH(B3,Resumo_NUTSIII!$A:$A,0))) -> 5.4
A4: Covilhã | B4: Cova da Beira | C4: =IF(B4="","",INDEX(Resumo_NUTSIII!$B:$B,MATCH(B4,Resumo_NUTSIII!$A:$A,0))) -> 1687 | D4: =IF(B4="","",INDEX(Resumo_NUTSIII!$C:$C,MATCH(B4,Resumo_NUTSIII!$A:$A,0))) -> 7.5 | E4: =IF(B4="","",INDEX(Resumo_NUTSIII!$D:$D,MATCH(B4,Resumo_NUTSIII!$A:$A,0))) -> 22.5 | F4: =IF(B4="","",INDEX(Resumo_NUTSIII!$E:$E,MATCH(B4,Resumo_NUTSIII!$A:$A,0))) -> 140 | G4: =IF(B4="","",INDEX(Resumo_NUTSIII!$F:$F,MATCH(B4,Resumo_NUTSIII!$A:$A,0))) -> 425 | H4: =IF(B4="","",INDEX(Resumo_NUTSIII!$G:$G,MATCH(B4,Resumo_NUTSIII!$A:$A,0))) -> 495 | I4: =IF(B4="","",INDEX(Resumo_NUTSIII!$H:$H,MATCH(B4,Resumo_NUTSIII!$A:$A,0))) -> 225 | J4: =IF(B4="","",INDEX(Resumo_NUTSIII!$I:$I,MATCH(B4,Resumo_NUTSIII!$A:$A,0))) -> 495 | K4: =IF(B4="","",INDEX(Resumo_NUTSIII!$J:$J,MATCH(B4,Resumo_NUTSIII!$A:$A,0))) -> 507 | L4: =IF(B4="","",INDEX(Resumo_NUTSIII!$K:$K,MATCH(B4,Resumo_NUTSIII!$A:$A,0))) -> 7.1
A5: Fundão | B5: Cova da Beira | C5: =IF(B5="","",INDEX(Resumo_NUTSIII!$B:$B,MATCH(B5,Resumo_NUTSIII!$A:$A,0))) -> 1687 | D5: =IF(B5="","",INDEX(Resumo_NUTSIII!$C:$C,MATCH(B5,Resumo_NUTSIII!$A:$A,0))) -> 7.5 | E5: =IF(B5="","",INDEX(Resumo_NUTSIII!$D:$D,MATCH(B5,Resumo_NUTSIII!$A:$A,0))) -> 22.5 | F5: =IF(B5="","",INDEX(Resumo_NUTSIII!$E:$E,MATCH(B5,Resumo_NUTSIII!$A:$A,0))) -> 140 | G5: =IF(B5="","",INDEX(Resumo_NUTSIII!$F:$F,MATCH(B5,Resumo_NUTSIII!$A:$A,0))) -> 425 | H5: =IF(B5="","",INDEX(Resumo_NUTSIII!$G:$G,MATCH(B5,Resumo_NUTSIII!$A:$A,0))) -> 495 | I5: =IF(B5="","",INDEX(Resumo_NUTSIII!$H:$H,MATCH(B5,Resumo_NUTSIII!$A:$A,0))) -> 225 | J5: =IF(B5="","",INDEX(Resumo_NUTSIII!$I:$I,MATCH(B5,Resumo_NUTSIII!$A:$A,0))) -> 495 | K5: =IF(B5="","",INDEX(Resumo_NUTSIII!$J:$J,MATCH(B5,Resumo_NUTSIII!$A:$A,0))) -> 507 | L5: =IF(B5="","",INDEX(Resumo_NUTSIII!$K:$K,MATCH(B5,Resumo_NUTSIII!$A:$A,0))) -> 7.1
A6: Idanha-a-Nova | B6: Beira Interior Sul | C6: =IF(B6="","",INDEX(Resumo_NUTSIII!$B:$B,MATCH(B6,Resumo_NUTSIII!$A:$A,0))) -> 1274 | D6: =IF(B6="","",INDEX(Resumo_NUTSIII!$C:$C,MATCH(B6,Resumo_NUTSIII!$A:$A,0))) -> 9.1 | E6: =IF(B6="","",INDEX(Resumo_NUTSIII!$D:$D,MATCH(B6,Resumo_NUTSIII!$A:$A,0))) -> 25.3 | F6: =IF(B6="","",INDEX(Resumo_NUTSIII!$E:$E,MATCH(B6,Resumo_NUTSIII!$A:$A,0))) -> 140 | G6: =IF(B6="","",INDEX(Resumo_NUTSIII!$F:$F,MATCH(B6,Resumo_NUTSIII!$A:$A,0))) -> 420 | H6: =IF(B6="","",INDEX(Resumo_NUTSIII!$G:$G,MATCH(B6,Resumo_NUTSIII!$A:$A,0))) -> 500 | I6: =IF(B6="","",INDEX(Resumo_NUTSIII!$H:$H,MATCH(B6,Resumo_NUTSIII!$A:$A,0))) -> 220 | J6: =IF(B6="","",INDEX(Resumo_NUTSIII!$I:$I,MATCH(B6,Resumo_NUTSIII!$A:$A,0))) -> 500 | K6: =IF(B6="","",INDEX(Resumo_NUTSIII!$J:$J,MATCH(B6,Resumo_NUTSIII!$A:$A,0))) -> 328 | L6: =IF(B6="","",INDEX(Resumo_NUTSIII!$K:$K,MATCH(B6,Resumo_NUTSIII!$A:$A,0))) -> 5.4
A7: Oleiros | B7: Pinhal Interior Sul | C7: =IF(B7="","",INDEX(Resumo_NUTSIII!$B:$B,MATCH(B7,Resumo_NUTSIII!$A:$A,0))) -> 1511 | D7: =IF(B7="","",INDEX(Resumo_NUTSIII!$C:$C,MATCH(B7,Resumo_NUTSIII!$A:$A,0))) -> 8.4 | E7: =IF(B7="","",INDEX(Resumo_NUTSIII!$D:$D,MATCH(B7,Resumo_NUTSIII!$A:$A,0))) -> 22.4 | F7: =IF(B7="","",INDEX(Resumo_NUTSIII!$E:$E,MATCH(B7,Resumo_NUTSIII!$A:$A,0))) -> 145 | G7: =IF(B7="","",INDEX(Resumo_NUTSIII!$F:$F,MATCH(B7,Resumo_NUTSIII!$A:$A,0))) -> 420 | H7: =IF(B7="","",INDEX(Resumo_NUTSIII!$G:$G,MATCH(B7,Resumo_NUTSIII!$A:$A,0))) -> 500 | I7: =IF(B7="","",INDEX(Resumo_NUTSIII!$H:$H,MATCH(B7,Resumo_NUTSIII!$A:$A,0))) -> 225 | J7: =IF(B7="","",INDEX(Resumo_NUTSIII!$I:$I,MATCH(B7,Resumo_NUTSIII!$A:$A,0))) -> 500 | K7: =IF(B7="","",INDEX(Resumo_NUTSIII!$J:$J,MATCH(B7,Resumo_NUTSIII!$A:$A,0))) -> 361 | L7: =IF(B7="","",INDEX(Resumo_NUTSIII!$K:$K,MATCH(B7,Resumo_NUTSIII!$A:$A,0))) -> 6.7
A8: Penamacor | B8: Cova da Beira | C8: =IF(B8="","",INDEX(Resumo_NUTSIII!$B:$B,MATCH(B8,Resumo_NUTSIII!$A:$A,0))) -> 1687 | D8: =IF(B8="","",INDEX(Resumo_NUTSIII!$C:$C,MATCH(B8,Resumo_NUTSIII!$A:$A,0))) -> 7.5 | E8: =IF(B8="","",INDEX(Resumo_NUTSIII!$D:$D,MATCH(B8,Resumo_NUTSIII!$A:$A,0))) -> 22.5 | F8: =IF(B8="","",INDEX(Resumo_NUTSIII!$E:$E,MATCH(B8,Resumo_NUTSIII!$A:$A,0))) -> 140 | G8: =IF(B8="","",INDEX(Resumo_NUTSIII!$F:$F,MATCH(B8,Resumo_NUTSIII!$A:$A,0))) -> 425 | H8: =IF(B8="","",INDEX(Resumo_NUTSIII!$G:$G,MATCH(B8,Resumo_NUTSIII!$A:$A,0))) -> 495 | I8: =IF(B8="","",INDEX(Resumo_NUTSIII!$H:$H,MATCH(B8,Resumo_NUTSIII!$A:$A,0))) -> 225 | J8: =IF(B8="","",INDEX(Resumo_NUTSIII!$I:$I,MATCH(B8,Resumo_NUTSIII!$A:$A,0))) -> 495 | K8: =IF(B8="","",INDEX(Resumo_NUTSIII!$J:$J,MATCH(B8,Resumo_NUTSIII!$A:$A,0))) -> 507 | L8: =IF(B8="","",INDEX(Resumo_NUTSIII!$K:$K,MATCH(B8,Resumo_NUTSIII!$A:$A,0))) -> 7.1
A9: Proença-a-Nova | B9: Pinhal Interior Sul | C9: =IF(B9="","",INDEX(Resumo_NUTSIII!$B:$B,MATCH(B9,Resumo_NUTSIII!$A:$A,0))) -> 1511 | D9: =IF(B9="","",INDEX(Resumo_NUTSIII!$C:$C,MATCH(B9,Resumo_NUTSIII!$A:$A,0))) -> 8.4 | E9: =IF(B9="","",INDEX(Resumo_NUTSIII!$D:$D,MATCH(B9,Resumo_NUTSIII!$A:$A,0))) -> 22.4 | F9: =IF(B9="","",INDEX(Resumo_NUTSIII!$E:$E,MATCH(B9,Resumo_NUTSIII!$A:$A,0))) -> 145 | G9: =IF(B9="","",INDEX(Resumo_NUTSIII!$F:$F,MATCH(B9,Resumo_NUTSIII!$A:$A,0))) -> 420 | H9: =IF(B9="","",INDEX(Resumo_NUTSIII!$G:$G,MATCH(B9,Resumo_NUTSIII!$A:$A,0))) -> 500 | I9: =IF(B9="","",INDEX(Resumo_NUTSIII!$H:$H,MATCH(B9,Resumo_NUTSIII!$A:$A,0))) -> 225 | J9: =IF(B9="","",INDEX(Resumo_NUTSIII!$I:$I,MATCH(B9,Resumo_NUTSIII!$A:$A,0))) -> 500 | K9: =IF(B9="","",INDEX(Resumo_NUTSIII!$J:$J,MATCH(B9,Resumo_NUTSIII!$A:$A,0))) -> 361 | L9: =IF(B9="","",INDEX(Resumo_NUTSIII!$K:$K,MATCH(B9,Resumo_NUTSIII!$A:$A,0))) -> 6.7
